Workbook

Sheet VENTAS
A1: PRODUCTOS | B1: COSTO | C1: PRECIO SUGERIDO | D1: precio | E1: cantidad | F1: 45246 | G1: otro precio | H1: =SUM(F2:F25)+SUM(H2:H17) -> 323000 | J1: precio | K1: cantidad | L1: 45247 | M1: otro precio | N1: =SUM(L2:L26)+SUM(N2:N24) -> 210000 | O1: precio | P1: cantidad | Q1: 45250 | R1: otro precio | S1: =sum(Q2:Q24)+SUM(S2:S24) -> 56000 | T1: precio | U1: cantidad | V1: 45253 | W1: otro precio | X1: =sum(V2:V25)+SUM(X2:X25) -> 218200 | Y1: precio | Z1: cantidad | AA1: 45254 | AB1: otro precio | AC1: =SUM(AA2:AA26)+SUM(AC2:AC24) -> 266000 | AD1: precio | AE1: cantidad | AF1: 45255 | AG1: otro precio | AH1: =sum(AF2:AF27)+SUM(AH2:AH27) -> 334000 | AI1: precio | AJ1: cantidad | AK1: 45256 | AL1: otro precio | AM1: =sum(AK2:AK30)+SUM(AM2:AM30) -> 238000 | AN1: precio | AO1: cantidad | AP1: 45261 | AQ1: otro precio | AR1: =SUM(AP2:AP30)+SUM(AR2:AR30) -> 53000 | AS1: precio | AT1: cantidad | AU1: 45263 | AV1: otro precio | AW1: =sum(AU2:AU27)+SUM(AW2:AW27) -> 803000 | AX1: precio | AY1: cantidad | AZ1: 45267 | BA1: otro precio | BB1: =sum(AZ2:AZ30)+SUM(BB2:BB30) -> 111000 | BC1: precio | BD1: cantidad | BE1: 45270 | BF1: otro precio | BG1: =SUM(BE2:BE30)+SUM(BG2:BG30) -> 44000 | BH1: precio | BI1: cantidad | BJ1: 45272 | BK1: otro precio | BL1: =sum(BJ2:BJ27)+SUM(BL2:BL27) -> 110000 | BM1: precio | BN1: cantidad | BO1: 45274 | BP1: otro precio | BQ1: =sum(BO2:BO30)+SUM(BQ2:BQ30) -> 128000
A2: pin artesanal | B2: 14000 | C2: 18000 | D2: 18000 | E2: 0 | F2: =E2*D2 -> 0 | G2: 0 | H2: 0 | J2: 18000 | K2: 1 | L2: =K2*J2 -> 18000 | M2: 0 | N2: 0 | O2: 18000 | P2: 0 | Q2: =P2*O2 -> 0 | R2: 0 | S2: =R2*Q2 -> 0 | T2: 18000 | U2: 0 | V2: =U2*T2 -> 0 | W2: 0 | X2: 0 | Y2: 18000 | Z2: 0 | AA2: =Z2*Y2 -> 0 | AB2: 0 | AC2: 0 | AD2: 18000 | AE2: 0 | AF2: =AE2*AD2 -> 0 | AG2: 0 | AH2: 0 | AI2: 18000 | AJ2: 1 | AK2: =AJ2*AI2 -> 18000 | AL2: 0 | AM2: 0 | AN2: 18000 | AO2: 0 | AP2: =AO2*AN2 -> 0 | AQ2: 0 | AR2: =AQ2*AP2 -> 0 | AS2: 18000 | AT2: 1 | AU2: =AT2*AS2 -> 18000 | AV2: 0 | AW2: 0 | AX2: 18000 | AY2: 0 | AZ2: =AY2*AX2 -> 0 | BA2: 0 | BB2: 0 | BC2: 18000 | BD2: 0 | BE2: =BD2*BC2 -> 0 | BF2: 0 | BG2: 0 | BH2: 18000 | BI2: 0 | BJ2: =BI2*BH2 -> 0 | BK2: 0 | BL2: 0 | BM2: 18000 | BN2: 0 | BO2: =BN2*BM2 -> 0 | BP2: 0 | BQ2: 0
A3: pin metálico | B3: 7000 | C3: 10000 | D3: 10000 | E3: 4 | F3: =E3*D3 -> 40000 | G3: 1 | H3: 7000 | J3: 10000 | K3: 2 | L3: =K3*J3 -> 20000 | M3: 0 | N3: 0 | O3: 10000 | P3: 0 | Q3: =P3*O3 -> 0 | R3: 0 | S3: =R3*Q3 -> 0 | T3: 10000 | U3: 4 | V3: =U3*T3 -> 40000 | W3: 0 | X3: =8400*5 -> 42000 | Y3: 10000 | Z3: 2 | AA3: =Z3*Y3 -> 20000 | AB3: 0 | AC3: 0 | AD3: 10000 | AE3: 3 | AF3: =AE3*AD3 -> 30000 | AG3: 0 | AH3: 0 | AI3: 10000 | AJ3: 2 | AK3: =AJ3*AI3 -> 20000 | AL3: 0 | AM3: 0 | AN3: 10000 | AO3: 3 | AP3: =AO3*AN3 -> 30000 | AQ3: 1 | AR3: 8000 | AS3: 10000 | AT3: 13 | AU3: =AT3*AS3 -> 130000 | AV3: 0 | AW3: 0 | AX3: 10000 | AY3: 1 | AZ3: =AY3*AX3 -> 10000 | BA3: 0 | BB3: 0 | BC3: 10000 | BD3: 1 | BE3: =BD3*BC3 -> 10000 | BF3: 0 | BG3: 0 | BH3: 10000 | BI3: 0 | BJ3: =BI3*BH3 -> 0 | BK3: 0 | BL3: 0 | BM3: 10000 | BN3: 0 | BO3: =BN3*BM3 -> 0 | BP3: 0 | BQ3: 0
A4: lápices | B4: 3000 | C4: 4000 | D4: 3000 | E4: 3 | F4: =E4*D4 -> 9000 | G4: 0 | H4: 0 | J4: 4000 | K4: 7 | L4: =K4*J4 -> 28000 | M4: 0 | N4: 0 | O4: 4000 | P4: 1 | Q4: =P4*O4 -> 4000 | R4: 0 | S4: =R4*Q4 -> 0 | T4: 4000 | U4: 0 | V4: =U4*T4 -> 0 | W4: 0 | X4: 0 | Y4: 4000 | Z4: 4 | AA4: =Z4*Y4 -> 16000 | AB4: 0 | AC4: 0 | AD4: 4000 | AE4: 5 | AF4: =AE4*AD4 -> 20000 | AG4: 0 | AH4: 0 | AI4: 4000 | AJ4: 0 | AK4: =AJ4*AI4 -> 0 | AL4: 0 | AM4: 0 | AN4: 4000 | AO4: 0 | AP4: =AO4*AN4 -> 0 | AQ4: 0 | AR4: =AQ4*AP4 -> 0 | AS4: 4000 | AT4: 4 | AU4: =AT4*AS4 -> 16000 | AV4: 0 | AW4: 0 | AX4: 4000 | AY4: 0 | AZ4: =AY4*AX4 -> 0 | BA4: 0 | BB4: 0 | BC4: 4000 | BD4: 0 | BE4: =BD4*BC4 -> 0 | BF4: 0 | BG4: 0 | BH4: 4000 | BI4: 0 | BJ4: =BI4*BH4 -> 0 | BK4: 0 | BL4: 0 | BM4: 4000 | BN4: 0 | BO4: =BN4*BM4 -> 0 | BP4: 0 | BQ4: 0
A5: esfero astronauta | B5: 6000 | C5: 10000 | D5: 10000 | E5: 3 | F5: =E5*D5 -> 30000 | G5: 0 | H5: 0 | J5: 10000 | K5: 1 | L5: =K5*J5 -> 10000 | M5: 0 | N5: 0 | O5: 10000 | P5: 0 | Q5: =P5*O5 -> 0 | R5: 0 | S5: =R5*Q5 -> 0 | T5: 10000 | U5: 0 | V5: =U5*T5 -> 0 | W5: 0 | X5: 0 | Y5: 10000 | Z5: 5 | AA5: =Z5*Y5 -> 50000 | AB5: 0 | AC5: 0 | AD5: 10000 | AE5: 6 | AF5: =AE5*AD5 -> 60000 | AG5: 0 | AH5: 0 | AI5: 10000 | AJ5: 0 | AK5: =AJ5*AI5 -> 0 | AL5: 0 | AM5: 0 | AN5: 10000 | AO5: 0 | AP5: =AO5*AN5 -> 0 | AQ5: 0 | AR5: =AQ5*AP5 -> 0 | AS5: 10000 | AT5: 4 | AU5: =AT5*AS5 -> 40000 | AV5: 0 | AW5: 0 | AX5: 10000 | AY5: 4 | AZ5: =AY5*AX5 -> 40000 | BA5: 0 | BB5: 0 | BC5: 10000 | BD5: 0 | BE5: =BD5*BC5 -> 0 | BF5: 0 | BG5: 0 | BH5: 10000 | BI5: 2 | BJ5: =BI5*BH5 -> 20000 | BK5: 0 | BL5: =BK5*8000 -> 0 | BM5: 10000 | BN5: 0 | BO5: =BN5*BM5 -> 0 | BP5: 12 | BQ5: =BP5*8000 -> 96000
A6: libreta | B6: 7000 | C6: 10000 | D6: 10000 | E6: 7 | F6: =E6*D6 -> 70000 | G6: 0 | H6: 0 | J6: 10000 | K6: 1 | L6: =K6*J6 -> 10000 | M6: 0 | N6: 0 | O6: 10000 | P6: 0 | Q6: =P6*O6 -> 0 | R6: 0 | S6: =R6*Q6 -> 0 | T6: 10000 | U6: 0 | V6: =U6*T6 -> 0 | W6: 0 | X6: 0 | Y6: 10000 | Z6: 0 | AA6: =Z6*Y6 -> 0 | AB6: 0 | AC6: 0 | AD6: 10000 | AE6: 1 | AF6: =AE6*AD6 -> 10000 | AG6: 0 | AH6: 0 | AI6: 10000 | AJ6: 0 | AK6: =AJ6*AI6 -> 0 | AL6: 0 | AM6: 0 | AN6: 10000 | AO6: 0 | AP6: =AO6*AN6 -> 0 | AQ6: 0 | AR6: =AQ6*AP6 -> 0 | AS6: 10000 | AT6: 0 | AU6: =AT6*AS6 -> 0 | AV6: 0 | AW6: 0 | AX6: 10000 | AY6: 0 | AZ6: =AY6*AX6 -> 0 | BA6: 0 | BB6: 0 | BC6: 10000 | BD6: 0 | BE6: =BD6*BC6 -> 0 | BF6: 0 | BG6: 0 | BH6: 10000 | BI6: 0 | BJ6: =BI6*BH6 -> 0 | BK6: 0 | BL6: 0 | BM6: 10000 | BN6: 0 | BO6: =BN6*BM6 -> 0 | BP6: 0 | BQ6: 0
A7: adhesivo luminoso | B7: 5000 | C7: 10000 | D7: 10000 | E7: 7 | F7: =E7*D7 -> 70000 | G7: 0 | H7: 0 | J7: 10000 | K7: 1 | L7: =K7*J7 -> 10000 | M7: 0 | N7: 0 | O7: 10000 | P7: 0 | Q7: =P7*O7 -> 0 | R7: 0 | S7: =R7*Q7 -> 0 | T7: 10000 | U7: 0 | V7: =U7*T7 -> 0 | W7: 0 | X7: 0 | Y7: 10000 | Z7: 4 | AA7: =Z7*Y7 -> 40000 | AB7: 0 | AC7: 0 | AD7: 10000 | AE7: 4 | AF7: =AE7*AD7 -> 40000 | AG7: 0 | AH7: 0 | AI7: 10000 | AJ7: 0 | AK7: =AJ7*AI7 -> 0 | AL7: 0 | AM7: 0 | AN7: 10000 | AO7: 0 | AP7: =AO7*AN7 -> 0 | AQ7: 0 | AR7: =AQ7*AP7 -> 0 | AS7: 10000 | AT7: 3 | AU7: =AT7*AS7 -> 30000 | AV7: 0 | AW7: 0 | AX7: 10000 | AY7: 0 | AZ7: =AY7*AX7 -> 0 | BA7: 0 | BB7: 0 | BC7: 10000 | BD7: 0 | BE7: =BD7*BC7 -> 0 | BF7: 0 | BG7: 0 | BH7: 10000 | BI7: 0 | BJ7: =BI7*BH7 -> 0 | BK7: 0 | BL7: 0 | BM7: 10000 | BN7: 0 | BO7: =BN7*BM7 -> 0 | BP7: 0 | BQ7: 0
A8: cartuchera | B8: 8000 | C8: 12000 | D8: 15000 | E8: 1 | F8: =E8*D8 -> 15000 | G8: 0 | H8: 0 | J8: 12000 | K8: 2 | L8: =K8*J8 -> 24000 | M8: 0 | N8: 0 | O8: 12000 | P8: 0 | Q8: =P8*O8 -> 0 | R8: 0 | S8: =R8*Q8 -> 0 | T8: 12000 | U8: 0 | V8: =U8*T8 -> 0 | W8: 0 | X8: 0 | Y8: 12000 | Z8: 0 | AA8: =Z8*Y8 -> 0 | AB8: 0 | AC8: 0 | AD8: 12000 | AE8: 0 | AF8: =AE8*AD8 -> 0 | AG8: 0 | AH8: 0 | AI8: 12000 | AJ8: 0 | AK8: =AJ8*AI8 -> 0 | AL8: 0 | AM8: 0 | AN8: 12000 | AO8: 0 | AP8: =AO8*AN8 -> 0 | AQ8: 0 | AR8: =AQ8*AP8 -> 0 | AS8: 12000 | AT8: 1 | AU8: =AT8*AS8 -> 12000 | AV8: 0 | AW8: 0 | AX8: 12000 | AY8: 0 | AZ8: =AY8*AX8 -> 0 | BA8: 0 | BB8: 0 | BC8: 12000 | BD8: 0 | BE8: =BD8*BC8 -> 0 | BF8: 0 | BG8: 0 | BH8: 12000 | BI8: 0 | BJ8: =BI8*BH8 -> 0 | BK8: 0 | BL8: 0 | BM8: 12000 | BN8: 0 | BO8: =BN8*BM8 -> 0 | BP8: 0 | BQ8: 0
A9: monedero | B9: 6000 | C9: 10000 | D9: 10000 | E9: 1 | F9: =E9*D9 -> 10000 | G9: 0 | H9: 0 | J9: 10000 | K9: 0 | L9: =K9*J9 -> 0 | M9: 0 | N9: 0 | O9: 10000 | P9: 1 | Q9: =P9*O9 -> 10000 | R9: 0 | S9: =R9*Q9 -> 0 | T9: 10000 | U9: 0 | V9: =U9*T9 -> 0 | W9: 0 | X9: 0 | Y9: 10000 | Z9: 0 | AA9: =Z9*Y9 -> 0 | AB9: 0 | AC9: 0 | AD9: 10000 | AE9: 1 | AF9: =AE9*AD9 -> 10000 | AG9: 0 | AH9: 0 | AI9: 10000 | AJ9: 2 | AK9: =AJ9*AI9 -> 20000 | AL9: 0 | AM9: 0 | AN9: 10000 | AO9: 0 | AP9: =AO9*AN9 -> 0 | AQ9: 0 | AR9: =AQ9*AP9 -> 0 | AS9: 10000 | AT9: 9 | AU9: =AT9*AS9 -> 90000 | AV9: 0 | AW9: 0 | AX9: 10000 | AY9: 0 | AZ9: =AY9*AX9 -> 0 | BA9: 0 | BB9: 0 | BC9: 10000 | BD9: 0 | BE9: =BD9*BC9 -> 0 | BF9: 0 | BG9: 0 | BH9: 10000 | BI9: 2 | BJ9: =BI9*BH9 -> 20000 | BK9: 0 | BL9: 0 | BM9: 10000 | BN9: 0 | BO9: =BN9*BM9 -> 0 | BP9: 0 | BQ9: 0
A10: cuaderno para colorear | B10: 10000 | C10: 15000 | D10: 15000 | E10: 2 | F10: =E10*D10 -> 30000 | G10: 0 | H10: 0 | J10: 15000 | K10: 0 | L10: =K10*J10 -> 0 | M10: 0 | N10: 0 | O10: 15000 | P10: 0 | Q10: =P10*O10 -> 0 | R10: 0 | S10: =R10*Q10 -> 0 | T10: 15000 | U10: 0 | V10: =U10*T10 -> 0 | W10: 0 | X10: 0 | Y10: 15000 | Z10: 0 | AA10: =Z10*Y10 -> 0 | AB10: 0 | AC10: 0 | AD10: 15000 | AE10: 0 | AF10: =AE10*AD10 -> 0 | AG10: 0 | AH10: 0 | AI10: 15000 | AJ10: 0 | AK10: =AJ10*AI10 -> 0 | AL10: 0 | AM10: 0 | AN10: 15000 | AO10: 0 | AP10: =AO10*AN10 -> 0 | AQ10: 0 | AR10: =AQ10*AP10 -> 0 | AS10: 15000 | AT10: 0 | AU10: =AT10*AS10 -> 0 | AV10: 0 | AW10: 0 | AX10: 15000 | AY10: 0 | AZ10: =AY10*AX10 -> 0 | BA10: 0 | BB10: 0 | BC10: 15000 | BD10: 0 | BE10: =BD10*BC10 -> 0 | BF10: 0 | BG10: 0 | BH10: 15000 | BI10: 0 | BJ10: =BI10*BH10 -> 0 | BK10: 0 | BL10: 0 | BM10: 15000 | BN10: 0 | BO10: =BN10*BM10 -> 0 | BP10: 0 | BQ10: 0
A11: manilla eclipse sol | B11: 1500 | C11: 2500 | D11: 2500 | E11: 1 | F11: =E11*D11 -> 2500 | G11: 1 | H11: 1500 | J11: 2500 | K11: 2 | L11: =K11*J11 -> 5000 | M11: 0 | N11: 0 | O11: 2500 | P11: 0 | Q11: =P11*O11 -> 0 | R11: 0 | S11: =R11*Q11 -> 0 | T11: 2500 | U11: 0 | V11: =U11*T11 -> 0 | W11: 0 | X11: 0 | Y11: 2500 | Z11: 0 | AA11: =Z11*Y11 -> 0 | AB11: 0 | AC11: 0 | AD11: 2500 | AE11: 0 | AF11: =AE11*AD11 -> 0 | AG11: 1 | AH11: 2000 | AI11: 2500 | AJ11: 0 | AK11: =AJ11*AI11 -> 0 | AL11: 1 | AM11: 2000 | AN11: 2500 | AO11: 0 | AP11: =AO11*AN11 -> 0 | AQ11: 0 | AR11: =AQ11*AP11 -> 0 | AS11: 2500 | AT11: 4 | AU11: =AT11*AS11 -> 10000 | AV11: 1 | AW11: 3000 | AX11: 2500 | AY11: 0 | AZ11: =AY11*AX11 -> 0 | BA11: 0 | BB11: 0 | BC11: 2500 | BD11: 0 | BE11: =BD11*BC11 -> 0 | BF11: 0 | BG11: 0 | BH11: 2500 | BI11: 0 | BJ11: =BI11*BH11 -> 0 | BK11: 0 | BL11: 0 | BM11: 2500 | BN11: 0 | BO11: =BN11*BM11 -> 0 | BP11: 0 | BQ11: 0
A12: manilla eclipse luna | B12: 1500 | C12: 2500 | D12: 2500 | E12: 0 | F12: =E12*D12 -> 0 | G12: 1 | H12: 1000 | J12: 2500 | K12: 1 | L12: =K12*J12 -> 2500 | M12: 0 | N12: 0 | O12: 2500 | P12: 0 | Q12: =P12*O12 -> 0 | R12: 0 | S12: =R12*Q12 -> 0 | T12: 2500 | U12: 0 | V12: =U12*T12 -> 0 | W12: 0 | X12: 0 | Y12: 2500 | Z12: 0 | AA12: =Z12*Y12 -> 0 | AB12: 0 | AC12: 0 | AD12: 2500 | AE12: 0 | AF12: =AE12*AD12 -> 0 | AG12: 1 | AH12: 2000 | AI12: 2500 | AJ12: 0 | AK12: =AJ12*AI12 -> 0 | AL12: 0 | AM12: 0 | AN12: 2500 | AO12: 0 | AP12: =AO12*AN12 -> 0 | AQ12: 0 | AR12: =AQ12*AP12 -> 0 | AS12: 2500 | AT12: 0 | AU12: =AT12*AS12 -> 0 | AV12: 0 | AW12: 0 | AX12: 2500 | AY12: 0 | AZ12: =AY12*AX12 -> 0 | BA12: 0 | BB12: 0 | BC12: 2500 | BD12: 0 | BE12: =BD12*BC12 -> 0 | BF12: 0 | BG12: 0 | BH12: 2500 | BI12: 0 | BJ12: =BI12*BH12 -> 0 | BK12: 0 | BL12: 0 | BM12: 2500 | BN12: 0 | BO12: =BN12*BM12 -> 0 | BP12: 0 | BQ12: 0
A13: manilla tatacoa | B13: 1500 | C13: 2500 | D13: 2500 | E13: 0 | F13: =E13*D13 -> 0 | G13: 0 | H13: 0 | J13: 2500 | K13: 1 | L13: =K13*J13 -> 2500 | M13: 0 | N13: 0 | O13: 2500 | P13: 0 | Q13: =P13*O13 -> 0 | R13: 0 | S13: =R13*Q13 -> 0 | T13: 2500 | U13: 0 | V13: =U13*T13 -> 0 | W13: 3 | X13: 3600 | Y13: 2500 | Z13: 0 | AA13: =Z13*Y13 -> 0 | AB13: 0 | AC13: 0 | AD13: 2500 | AE13: 0 | AF13: =AE13*AD13 -> 0 | AG13: 0 | AH13: 0 | AI13: 2500 | AJ13: 0 | AK13: =AJ13*AI13 -> 0 | AL13: 0 | AM13: 0 | AN13: 2500 | AO13: 0 | AP13: =AO13*AN13 -> 0 | AQ13: 0 | AR13: =AQ13*AP13 -> 0 | AS13: 2500 | AT13: 0 | AU13: =AT13*AS13 -> 0 | AV13: 0 | AW13: 0 | AX13: 2500 | AY13: 0 | AZ13: =AY13*AX13 -> 0 | BA13: 0 | BB13: 0 | BC13: 2500 | BD13: 0 | BE13: =BD13*BC13 -> 0 | BF13: 0 | BG13: 0 | BH13: 2500 | BI13: 0 | BJ13: =BI13*BH13 -> 0 | BK13: 0 | BL13: 0 | BM13: 2500 | BN13: 0 | BO13: =BN13*BM13 -> 0 | BP13: 0 | BQ13: 0
A14: fotos pequeñas | B14: 600 | C14: 2000 | D14: 1200 | E14: 0 | F14: =E14*D14 -> 0 | G14: 0 | H14: 0 | J14: 1500 | K14: 8 | L14: =K14*J14 -> 12000 | M14: 0 | N14: 0 | O14: 1500 | P14: 0 | Q14: =P14*O14 -> 0 | R14: 0 | S14: =R14*Q14 -> 0 | T14: 1500 | U14: 0 | V14: =U14*T14 -> 0 | W14: 5 | X14: 4400 | Y14: 1500 | Z14: 0 | AA14: =Z14*Y14 -> 0 | AB14: 0 | AC14: 0 | AD14: 1500 | AE14: 2 | AF14: =AE14*AD14 -> 3000 | AG14: 0 | AH14: 0 | AI14: 1500 | AJ14: 0 | AK14: =AJ14*AI14 -> 0 | AL14: 0 | AM14: 0 | AN14: 1500 | AO14: 0 | AP14: =AO14*AN14 -> 0 | AQ14: 0 | AR14: =AQ14*AP14 -> 0 | AS14: 2000 | AT14: 4 | AU14: =AT14*AS14 -> 8000 | AV14: 0 | AW14: 0 | AX14: 1500 | AY14: 2 | AZ14: =AY14*AX14 -> 3000 | BA14: 0 | BB14: 0 | BC14: 1500 | BD14: 0 | BE14: =BD14*BC14 -> 0 | BF14: 0 | BG14: 0 | BH14: 2000 | BI14: 0 | BJ14: =BI14*BH14 -> 0 | BK14: 0 | BL14: 0 | BM14: 1500 | BN14: 0 | BO14: =BN14*BM14 -> 0 | BP14: 0 | BQ14: 0
A15: fotos grandes | B15: 1000 | C15: 3000 | D15: 2000 | E15: 0 | F15: =E15*D15 -> 0 | G15: 0 | H15: 0 | J15: 3000 | K15: 7 | L15: =K15*J15 -> 21000 | M15: 1 | N15: 2000 | O15: 3000 | P15: 0 | Q15: =P15*O15 -> 0 | R15: 0 | S15: =R15*Q15 -> 0 | T15: 3000 | U15: 1 | V15: =U15*T15 -> 3000 | W15: 1 | X15: 1200 | Y15: 3000 | Z15: 0 | AA15: =Z15*Y15 -> 0 | AB15: 0 | AC15: 0 | AD15: 3000 | AE15: 0 | AF15: =AE15*AD15 -> 0 | AG15: 1 | AH15: 0 | AI15: 3000 | AJ15: 0 | AK15: =AJ15*AI15 -> 0 | AL15: 1 | AM15: 0 | AN15: 3000 | AO15: 0 | AP15: =AO15*AN15 -> 0 | AQ15: 0 | AR15: =AQ15*AP15 -> 0 | AS15: 3000 | AT15: 1 | AU15: =AT15*AS15 -> 3000 | AV15: 0 | AW15: 0 | AX15: 3000 | AY15: 2 | AZ15: =AY15*AX15 -> 6000 | BA15: 0 | BB15: 0 | BC15: 3000 | BD15: 0 | BE15: =BD15*BC15 -> 0 | BF15: 0 | BG15: 0 | BH15: 3000 | BI15: 0 | BJ15: =BI15*BH15 -> 0 | BK15: 0 | BL15: 0 | BM15: 3000 | BN15: 0 | BO15: =BN15*BM15 -> 0 | BP15: 0 | BQ15: 0
A16: aretes | B16: 12000 | C16: 15000 | D16: 12000 | E16: 1 | F16: =E16*D16 -> 12000 | G16: 0 | H16: 0 | J16: 15000 | K16: 3 | L16: =K16*J16 -> 45000 | M16: 0 | N16: 0 | O16: 15000 | P16: 0 | Q16: =P16*O16 -> 0 | R16: 0 | S16: =R16*Q16 -> 0 | T16: 15000 | U16: 0 | V16: =U16*T16 -> 0 | W16: 0 | X16: 0 | Y16: 15000 | Z16: 0 | AA16: =Z16*Y16 -> 0 | AB16: 0 | AC16: 0 | AD16: 15000 | AE16: 0 | AF16: =AE16*AD16 -> 0 | AG16: 0 | AH16: 0 | AI16: 15000 | AJ16: 0 | AK16: =AJ16*AI16 -> 0 | AL16: 0 | AM16: 0 | AN16: 15000 | AO16: 0 | AP16: =AO16*AN16 -> 0 | AQ16: 0 | AR16: =AQ16*AP16 -> 0 | AS16: 15000 | AT16: 0 | AU16: =AT16*AS16 -> 0 | AV16: 0 | AW16: 0 | AX16: 15000 | AY16: 2 | AZ16: =AY16*AX16 -> 30000 | BA16: 0 | BB16: 0 | BC16: 15000 | BD16: 0 | BE16: =BD16*BC16 -> 0 | BF16: 0 | BG16: 0 | BH16: 15000 | BI16: 0 | BJ16: =BI16*BH16 -> 0 | BK16: 0 | BL16: 0 | BM16: 15000 | BN16: 0 | BO16: =BN16*BM16 -> 0 | BP16: 0 | BQ16: 0
A17: carta celeste | B17: 25000 | C17: 25000 | D17: 25000 | E17: 1 | F17: =E17*D17 -> 25000 | G17: 0 | H17: 0 | J17: 25000 | K17: 0 | L17: =K17*J17 -> 0 | M17: 0 | N17: 0 | O17: 25000 | P17: 0 | Q17: =P17*O17 -> 0 | R17: 0 | S17: =R17*Q17 -> 0 | T17: 25000 | U17: 0 | V17: =U17*T17 -> 0 | W17: 0 | X17: 0 | Y17: 25000 | Z17: 0 | AA17: =Z17*Y17 -> 0 | AB17: 0 | AC17: 0 | AD17: 25000 | AE17: 0 | AF17: =AE17*AD17 -> 0 | AG17: 0 | AH17: 0 | AI17: 25000 | AJ17: 0 | AK17: =AJ17*AI17 -> 0 | AL17: 0 | AM17: 0 | AN17: 25000 | AO17: 0 | AP17: =AO17*AN17 -> 0 | AQ17: 0 | AR17: =AQ17*AP17 -> 0 | AS17: 25000 | AT17: 0 | AU17: =AT17*AS17 -> 0 | AV17: 0 | AW17: 0 | AX17: 25000 | AY17: 0 | AZ17: =AY17*AX17 -> 0 | BA17: 0 | BB17: 0 | BC17: 25000 | BD17: 0 | BE17: =BD17*BC17 -> 0 | BF17: 0 | BG17: 0 | BH17: 25000 | BI17: 0 | BJ17: =BI17*BH17 -> 0 | BK17: 0 | BL17: 0 | BM17: 25000 | BN17: 0 | BO17: =BN17*BM17 -> 0 | BP17: 0 | BQ17: 0
A18: bolsas de tela | B18: 15000 | C18: 20000 | O18: 20000 | P18: 0 | Q18: =P18*O18 -> 0 | R18: 0 | S18: =R18*Q18 -> 0 | T18: 20000 | U18: 0 | V18: =U18*T18 -> 0 | W18: 0 | X18: 0 | Y18: 20000 | Z18: 0 | AA18: =Z18*Y18 -> 0 | AB18: 0 | AC18: 0 | AD18: 20000 | AE18: 0 | AF18: =AE18*AD18 -> 0 | AG18: 0 | AH18: 0 | AI18: 20000 | AJ18: 0 | AK18: =AJ18*AI18 -> 0 | AL18: 0 | AM18: 0 | AN18: 20000 | AO18: 0 | AP18: =AO18*AN18 -> 0 | AQ18: 0 | AR18: =AQ18*AP18 -> 0 | AS18: 20000 | AT18: 1 | AU18: =AT18*AS18 -> 20000 | AV18: 0 | AW18: 0 | AX18: 20000 | AY18: 0 | AZ18: =AY18*AX18 -> 0 | BA18: 0 | BB18: 0 | BC18: 20000 | BD18: 0 | BE18: =BD18*BC18 -> 0 | BF18: 0 | BG18: 0 | BH18: 20000 | BI18: 0 | BJ18: =BI18*BH18 -> 0 | BK18: 0 | BL18: 0 | BM18: 20000 | BN18: 0 | BO18: =BN18*BM18 -> 0 | BP18: 0 | BQ18: 0
A19: esfero cohete | B19: 6000 | C19: 10000 | O19: 10000 | P19: 0 | Q19: =P19*O19 -> 0 | R19: 0 | S19: =R19*Q19 -> 0 | T19: 10000 | U19: 1 | V19: =U19*T19 -> 10000 | W19: 0 | X19: 0 | Y19: 10000 | Z19: 0 | AA19: =Z19*Y19 -> 0 | AB19: 0 | AC19: 0 | AD19: 10000 | AE19: 1 | AF19: =AE19*AD19 -> 10000 | AG19: 0 | AH19: 0 | AI19: 10000 | AJ19: 2 | AK19: =AJ19*AI19 -> 20000 | AL19: 0 | AM19: 0 | AN19: 10000 | AO19: 0 | AP19: =AO19*AN19 -> 0 | AQ19: 0 | AR19: =AQ19*AP19 -> 0 | AS19: 10000 | AT19: 5 | AU19: =AT19*AS19 -> 50000 | AV19: 0 | AW19: 0 | AX19: 10000 | AY19: 1 | AZ19: =AY19*AX19 -> 10000 | BA19: 0 | BB19: 0 | BC19: 10000 | BD19: 2 | BE19: =BD19*BC19 -> 20000 | BF19: 0 | BG19: 0 | BH19: 10000 | BI19: 0 | BJ19: =BI19*BH19 -> 0 | BK19: 0 | BL19: 0 | BM19: 10000 | BN19: 0 | BO19: =BN19*BM19 -> 0 | BP19: 4 | BQ19: =BP19*8000 -> 32000
A20: mousepad | B20: 9500 | C20: 12000 | O20: 12000 | P20: 1 | Q20: =P20*O20 -> 12000 | R20: 0 | S20: =R20*Q20 -> 0 | T20: 12000 | U20: 1 | V20: =U20*T20 -> 12000 | W20: 0 | X20: 0 | Y20: 12000 | Z20: 0 | AA20: =Z20*Y20 -> 0 | AB20: 0 | AC20: 0 | AD20: 12000 | AE20: 0 | AF20: =AE20*AD20 -> 0 | AG20: 0 | AH20: 0 | AI20: 12000 | AJ20: 1 | AK20: =AJ20*AI20 -> 12000 | AL20: 1 | AM20: 11000 | AN20: 12000 | AO20: 0 | AP20: =AO20*AN20 -> 0 | AQ20: 0 | AR20: =AQ20*AP20 -> 0 | AS20: 12000 | AT20: 4 | AU20: =AT20*AS20 -> 48000 | AV20: 0 | AW20: 0 | AX20: 12000 | AY20: 1 | AZ20: =AY20*AX20 -> 12000 | BA20: 0 | BB20: 0 | BC20: 12000 | BD20: 0 | BE20: =BD20*BC20 -> 0 | BF20: 0 | BG20: 0 | BH20: 12000 | BI20: 0 | BJ20: =BI20*BH20 -> 0 | BK20: 0 | BL20: 0 | BM20: 12000 | BN20: 0 | BO20: =BN20*BM20 -> 0 | BP20: 0 | BQ20: 0
A21: tula de planetas | B21: 14000 | C21: 20000 | O21: 18000 | P21: 0 | Q21: =P21*O21 -> 0 | R21: 0 | S21: =R21*Q21 -> 0 | T21: 18000 | U21: 0 | V21: =U21*T21 -> 0 | W21: 2 | X21: 40000 | Y21: 20000 | Z21: 0 | AA21: =Z21*Y21 -> 0 | AB21: 0 | AC21: 0 | AD21: 20000 | AE21: 1 | AF21: =AE21*AD21 -> 20000 | AG21: 0 | AH21: 0 | AI21: 20000 | AJ21: 1 | AK21: =AJ21*AI21 -> 20000 | AL21: 0 | AM21: 0 | AN21: 20000 | AO21: 0 | AP21: =AO21*AN21 -> 0 | AQ21: 0 | AR21: =AQ21*AP21 -> 0 | AS21: 20000 | AT21: 1 | AU21: =AT21*AS21 -> 20000 | AV21: 0 | AW21: 0 | AX21: 20000 | AY21: 0 | AZ21: =AY21*AX21 -> 0 | BA21: 0 | BB21: 0 | BC21: 20000 | BD21: 0 | BE21: =BD21*BC21 -> 0 | BF21: 0 | BG21: 0 | BH21: 20000 | BI21: 2 | BJ21: =BI21*BH21 -> 40000 | BK21: 0 | BL21: 0 | BM21: 20000 | BN21: 0 | BO21: =BN21*BM21 -> 0 | BP21: 0 | BQ21: 0
A22: cuadernos exploración | B22: 10000 | C22: 15000 | O22: 15000 | P22: 2 | Q22: =P22*O22 -> 30000 | R22: 0 | S22: =R22*Q22 -> 0 | T22: 15000 | U22: 0 | V22: =U22*T22 -> 0 | W22: 1 | X22: 12000 | Y22: 15000 | Z22: 2 | AA22: =Z22*Y22 -> 30000 | AB22: 0 | AC22: 0 | AD22: 15000 | AE22: 1 | AF22: =AE22*AD22 -> 15000 | AG22: 0 | AH22: 0 | AI22: 15000 | AJ22: 2 | AK22: =AJ22*AI22 -> 30000 | AL22: 0 | AM22: 0 | AN22: 15000 | AO22: 1 | AP22: =AO22*AN22 -> 15000 | AQ22: 0 | AR22: =AQ22*AP22 -> 0 | AS22: 15000 | AT22: 1 | AU22: =AT22*AS22 -> 15000 | AV22: 0 | AW22: 0 | AX22: 15000 | AY22: 0 | AZ22: =AY22*AX22 -> 0 | BA22: 0 | BB22: 0 | BC22: 15000 | BD22: 0 | BE22: =BD22*BC22 -> 0 | BF22: 0 | BG22: 0 | BH22: 15000 | BI22: 2 | BJ22: =BI22*BH22 -> 30000 | BK22: 0 | BL22: 0 | BM22: 15000 | BN22: 0 | BO22: =BN22*BM22 -> 0 | BP22: 0 | BQ22: 0
A23: gorras nasa | B23: 15000 | C23: 20000 | O23: 20000 | P23: 0 | Q23: =P23*O23 -> 0 | R23: 0 | S23: =R23*Q23 -> 0 | T23: 20000 | U23: 0 | V23: =U23*T23 -> 0 | W23: 0 | X23: 0 | Y23: 20000 | Z23: 0 | AA23: =Z23*Y23 -> 0 | AB23: 0 | AC23: 0 | AD23: 20000 | AE23: 1 | AF23: =AE23*AD23 -> 20000 | AG23: 0 | AH23: 0 | AI23: 20000 | AJ23: 0 | AK23: =AJ23*AI23 -> 0 | AL23: 1 | AM23: 18000 | AN23: 20000 | AO23: 0 | AP23: =AO23*AN23 -> 0 | AQ23: 0 | AR23: =AQ23*AP23 -> 0 | AS23: 20000 | AT23: 4 | AU23: =AT23*AS23 -> 80000 | AV23: 0 | AW23: 0 | AX23: 20000 | AY23: 0 | AZ23: =AY23*AX23 -> 0 | BA23: 0 | BB23: 0 | BC23: 20000 | BD23: 0 | BE23: =BD23*BC23 -> 0 | BF23: 0 | BG23: 0 | BH23: 20000 | BI23: 0 | BJ23: =BI23*BH23 -> 0 | BK23: 0 | BL23: 0 | BM23: 20000 | BN23: 0 | BO23: =BN23*BM23 -> 0 | BP23: 0 | BQ23: 0
A24: libro Juno | B24: 22000 | C24: 30000 | T24: 30000 | U24: 1 | V24: =U24*T24 -> 30000 | W24: 0 | X24: 0 | Y24: 30000 | Z24: 2 | AA24: =Z24*Y24 -> 60000 | AB24: 0 | AC24: 0 | AD24: 30000 | AE24: 1 | AF24: =AE24*AD24 -> 30000 | AG24: 0 | AH24: 0 | AI24: 30000 | AJ24: 1 | AK24: =AJ24*AI24 -> 30000 | AL24: 0 | AM24: 0 | AN24: 30000 | AO24: 0 | AP24: =AO24*AN24 -> 0 | AQ24: 0 | AR24: =AQ24*AP24 -> 0 | AS24: 30000 | AT24: 7 | AU24: =AT24*AS24 -> 210000 | AV24: 0 | AW24: 0 | AX24: 30000 | AY24: 0 | AZ24: =AY24*AX24 -> 0 | BA24: 0 | BB24: 0 | BC24: 30000 | BD24: 0 | BE24: =BD24*BC24 -> 0 | BF24: 0 | BG24: 0 | BH24: 30000 | BI24: 0 | BJ24: =BI24*BH24 -> 0 | BK24: 0 | BL24: 0 | BM24: 30000 | BN24: 0 | BO24: =BN24*BM24 -> 0 | BP24: 0 | BQ24: 0
A25: botilito | B25: 21000 | C25: 30000 | T25: 30000 | U25: 0 | V25: =U25*T25 -> 0 | W25: 1 | X25: 20000 | Y25: 25000 | Z25: 2 | AA25: =Z25*Y25 -> 50000 | AB25: 0 | AC25: 0 | AD25: 30000 | AE25: 0 | AF25: =AE25*AD25 -> 0 | AG25: 0 | AH25: 0 | AI25: 30000 | AJ25: 1 | AK25: =AJ25*AI25 -> 30000 | AL25: 0 | AM25: 0 | AN25: 30000 | AO25: 0 | AP25: =AO25*AN25 -> 0 | AQ25: 0 | AR25: =AQ25*AP25 -> 0 | AS25: 30000 | AT25: 0 | AU25: =AT25*AS25 -> 0 | AV25: 0 | AW25: 0 | AX25: 30000 | AY25: 0 | AZ25: =AY25*AX25 -> 0 | BA25: 0 | BB25: 0 | BC25: 30000 | BD25: 0 | BE25: =BD25*BC25 -> 0 | BF25: 0 | BG25: 0 | BH25: 30000 | BI25: 0 | BJ25: =BI25*BH25 -> 0 | BK25: 0 | BL25: 0 | BM25: 30000 | BN25: 0 | BO25: =BN25*BM25 -> 0 | BP25: 0 | BQ25: 0
A26: gafas de sol | B26: 0 | C26: 7000 | AD26: 7000 | AE26: 6 | AF26: =AE26*AD26 -> 42000 | AG26: 0 | AH26: 0 | AI26: 7000 | AJ26: 1 | AK26: =AJ26*AI26 -> 7000 | AL26: 0 | AM26: 0 | AN26: 7000 | AO26: 0 | AP26: =AO26*AN26 -> 0 | AQ26: 0 | AR26: =AQ26*AP26 -> 0 | AS26: 7000 | AT26: 0 | AU26: =AT26*AS26 -> 0 | AV26: 0 | AW26: 0 | AX26: 7000 | AY26: 0 | AZ26: =AY26*AX26 -> 0 | BA26: 0 | BB26: 0 | BC26: 7000 | BD26: 2 | BE26: =BD26*BC26 -> 14000 | BF26: 0 | BG26: 0 | BH26: 7000 | BI26: 0 | BJ26: =BI26*BH26 -> 0 | BK26: 0 | BL26: 0 | BM26: 7000 | BN26: 0 | BO26: =BN26*BM26 -> 0 | BP26: 0 | BQ26: 0
A27: cuello | B27: 0 | C27: 20000 | AD27: 20000 | AE27: 1 | AF27: =AE27*AD27 -> 20000 | AG27: 0 | AH27: 0 | AI27: 20000 | AJ27: 0 | AK27: =AJ27*AI27 -> 0 | AL27: 0 | AM27: 0 | AN27: 20000 | AO27: 0 | AP27: =AO27*AN27 -> 0 | AQ27: 0 | AR27: =AQ27*AP27 -> 0 | AS27: 20000 | AT27: 0 | AU27: =AT27*AS27 -> 0 | AV27: 0 | AW27: 0 | AX27: 20000 | AY27: 0 | AZ27: =AY27*AX27 -> 0 | BA27: 0 | BB27: 0 | BC27: 20000 | BD27: 0 | BE27: =BD27*BC27 -> 0 | BF27: 0 | BG27: 0 | BH27: 20000 | BI27: 0 | BJ27: =BI27*BH27 -> 0 | BK27: 0 | BL27: 0 | BM27: 20000 | BN27: 0 | BO27: =BN27*BM27 -> 0 | BP27: 0 | BQ27: 0

Sheet BALANCE
A1: BALANCE DE VENTAS | B1: TOTAL | C1: 45246 | D1: 45247 | E1: 45250 | F1: 45253 | G1: 45254 | H1: 45255 | I1: 45256 | J1: 45261 | K1: 45263 | L1: 45267 | M1: 45270 | N1: 45272 | O1: 45274
A2: dinero recaudado | B2: =SUM(C2:Y2) -> 2894200 | C2: =VENTAS!H1 -> 323000 | D2: =VENTAS!N1 -> 210000 | E2: =VENTAS!S1 -> 56000 | F2: =VENTAS!X1 -> 218200 | G2: =VENTAS!AC1 -> 266000 | H2: =VENTAS!AH1 -> 334000 | I2: =VENTAS!AM1 -> 238000 | J2: =VENTAS!AR1 -> 53000 | K2: =VENTAS!AW1 -> 803000 | L2: =VENTAS!BB1 -> 111000 | M2: =VENTAS!BG1 -> 44000 | N2: =VENTAS!BL1 -> 110000 | O2: =VENTAS!BQ1 -> 128000
A3: saldo proveedores | B3: =SUM(C3:Y3) -> 1881100 | C3: =C28+C31 -> 221500 | D3: =D28+D31 -> 137800 | E3: =E28+E31 -> 38500 | F3: =F28+F31+F33 -> 134000 | G3: =G28+G31+G33 -> 182000 | H3: =H28+H31+H33 -> 177200 | I3: =I28+I31+I33 -> 165500 | J3: =J28+J31+J33 -> 38000 | K3: =K28+K31+K33 -> 549900 | L3: =L28+L31+L33 -> 73700 | M3: =M28+M31+M33 -> 19000 | N3: =N28+N31+N33 -> 72000 | O3: 72000
A4: ganancias | B4: =B2-B3 -> 1013100 | C4: =C2-C3 -> 101500 | D4: =D2-D3 -> 72200 | E4: =E2-E3 -> 17500 | F4: =F2-F3 -> 84200 | G4: =G2-G3 -> 84000 | H4: =H2-H3 -> 156800 | I4: =I2-I3 -> 72500 | ... O4: =O2-O3 -> 56000
A6: producto | B6: costo unitario | C6: 45246 | D6: 45247 | E6: 45250 | F6: 45253 | G6: 45254 | H6: 45255 | I6: 45256 | J6: 45261 | K6: 45263 | L6: 45267 | M6: 45270 | N6: 45272 | O6: 45274
A7: pin artesanal | B7: 14000 | C7: =VENTAS!E2+VENTAS!G2 -> 0 | D7: =VENTAS!K2+VENTAS!M2 -> 1 | E7: =VENTAS!P2+VENTAS!R2 -> 0 | F7: =VENTAS!U2+VENTAS!W2 -> 0 | G7: =VENTAS!Z2+VENTAS!AB2 -> 0 | H7: =VENTAS!AE2+VENTAS!AG2 -> 0 | I7: =VENTAS!AJ2+VENTAS!AL2 -> 1 | J7: 0 | K7: =VENTAS!AT2+VENTAS!AV2 -> 1 | L7: =VENTAS!AY2+VENTAS!BA2 -> 0 | M7: 0 | N7: 0 | O7: 0
A8: pin metálico | B8: 7000 | C8: =VENTAS!E3+VENTAS!G3 -> 5 | D8: =VENTAS!K3+VENTAS!M3 -> 2 | E8: =VENTAS!P3+VENTAS!R3 -> 0 | F8: =VENTAS!U3+VENTAS!W3 -> 4 | G8: =VENTAS!Z3+VENTAS!AB3 -> 2 | H8: =VENTAS!AE3+VENTAS!AG3 -> 3 | I8: =VENTAS!AJ3+VENTAS!AL3 -> 2 | J8: 4 | K8: =VENTAS!AT3+VENTAS!AV3 -> 13 | L8: =VENTAS!AY3+VENTAS!BA3 -> 1 | M8: 1 | N8: 0 | O8: 0
A9: lápices | B9: 3000 | C9: =VENTAS!E4+VENTAS!G4 -> 3 | D9: =VENTAS!K4+VENTAS!M4 -> 7 | E9: =VENTAS!P4+VENTAS!R4 -> 1 | F9: =VENTAS!U4+VENTAS!W4 -> 0 | G9: =VENTAS!Z4+VENTAS!AB4 -> 4 | H9: =VENTAS!AE4+VENTAS!AG4 -> 5 | I9: =VENTAS!AJ4+VENTAS!AL4 -> 0 | J9: 0 | K9: =VENTAS!AT4+VENTAS!AV4 -> 4 | L9: =VENTAS!AY4+VENTAS!BA4 -> 0 | M9: 0 | N9: 0 | O9: 0
A10: esfero astronauta | B10: 6000 | C10: =VENTAS!E5+VENTAS!G5 -> 3 | D10: =VENTAS!K5+VENTAS!M5 -> 1 | E10: =VENTAS!P5+VENTAS!R5 -> 0 | F10: =VENTAS!U5+VENTAS!W5 -> 0 | G10: =VENTAS!Z5+VENTAS!AB5 -> 5 | H10: =VENTAS!AE5+VENTAS!AG5 -> 6 | I10: =VENTAS!AJ5+VENTAS!AL5 -> 0 | J10: 0 | K10: =VENTAS!AT5+VENTAS!AV5 -> 4 | L10: =VENTAS!AY5+VENTAS!BA5 -> 4 | M10: 0 | N10: 2 | O10: 12
A11: libreta | B11: 7000 | C11: =VENTAS!E6+VENTAS!G6 -> 7 | D11: =VENTAS!K6+VENTAS!M6 -> 1 | E11: =VENTAS!P6+VENTAS!R6 -> 0 | F11: =VENTAS!U6+VENTAS!W6 -> 0 | G11: =VENTAS!Z6+VENTAS!AB6 -> 0 | H11: =VENTAS!AE6+VENTAS!AG6 -> 1 | I11: =VENTAS!AJ6+VENTAS!AL6 -> 0 | J11: 0 | K11: =VENTAS!AT6+VENTAS!AV6 -> 0 | L11: =VENTAS!AY6+VENTAS!BA6 -> 0 | M11: 0 | N11: 0 | O11: 0
A12: adhesivo luminoso | B12: 5000 | C12: =VENTAS!E7+VENTAS!G7 -> 7 | D12: =VENTAS!K7+VENTAS!M7 -> 1 | E12: =VENTAS!P7+VENTAS!R7 -> 0 | F12: =VENTAS!U7+VENTAS!W7 -> 0 | G12: =VENTAS!Z7+VENTAS!AB7 -> 4 | H12: =VENTAS!AE7+VENTAS!AG7 -> 4 | I12: =VENTAS!AJ7+VENTAS!AL7 -> 0 | J12: 0 | K12: =VENTAS!AT7+VENTAS!AV7 -> 3 | L12: =VENTAS!AY7+VENTAS!BA7 -> 0 | M12: 0 | N12: 0 | O12: 0
A13: cartuchera | B13: 8000 | C13: =VENTAS!E8+VENTAS!G8 -> 1 | D13: =VENTAS!K8+VENTAS!M8 -> 2 | E13: =VENTAS!P8+VENTAS!R8 -> 0 | F13: =VENTAS!U8+VENTAS!W8 -> 0 | G13: =VENTAS!Z8+VENTAS!AB8 -> 0 | H13: =VENTAS!AE8+VENTAS!AG8 -> 0 | I13: =VENTAS!AJ8+VENTAS!AL8 -> 0 | J13: 0 | K13: =VENTAS!AT8+VENTAS!AV8 -> 1 | L13: =VENTAS!AY8+VENTAS!BA8 -> 0 | M13: 0 | N13: 0 | O13: 0
A14: monedero | B14: 6000 | C14: =VENTAS!E9+VENTAS!G9 -> 1 | D14: =VENTAS!K9+VENTAS!M9 -> 0 | E14: =VENTAS!P9+VENTAS!R9 -> 1 | F14: =VENTAS!U9+VENTAS!W9 -> 0 | G14: =VENTAS!Z9+VENTAS!AB9 -> 0 | H14: =VENTAS!AE9+VENTAS!AG9 -> 1 | I14: =VENTAS!AJ9+VENTAS!AL9 -> 2 | J14: 0 | K14: =VENTAS!AT9+VENTAS!AV9 -> 9 | L14: =VENTAS!AY9+VENTAS!BA9 -> 0 | M14: 0 | N14: 2 | O14: 0
A15: cuaderno para colorear | B15: 10000 | C15: =VENTAS!E10+VENTAS!G10 -> 2 | D15: - | E15: - | F15: =VENTAS!U10+VENTAS!W10 -> 0 | G15: - | H15: - | I15: - | J15: - | K15: - | L15: =VENTAS!AY10+VENTAS!BA10 -> 0 | M15: 0 | N15: 0 | O15: 0
A16: manilla eclipse sol | B16: 1500 | C16: =VENTAS!E11+VENTAS!G11 -> 2 | D16: =VENTAS!K11+VENTAS!M11 -> 2 | E16: =VENTAS!P11+VENTAS!R11 -> 0 | F16: =VENTAS!U11+VENTAS!W11 -> 0 | G16: =VENTAS!Z11+VENTAS!AB11 -> 0 | H16: =VENTAS!AE11+VENTAS!AG11 -> 1 | I16: =VENTAS!AJ11+VENTAS!AL11 -> 1 | J16: 0 | K16: =VENTAS!AT11+VENTAS!AV11 -> 5 | L16: =VENTAS!AY11+VENTAS!BA11 -> 0 | M16: 0 | N16: 0 | O16: 0
A17: manilla eclipse luna | B17: 1500 | C17: =VENTAS!E12+VENTAS!G12 -> 1 | D17: =VENTAS!K12+VENTAS!M12 -> 1 | E17: =VENTAS!P12+VENTAS!R12 -> 0 | F17: =VENTAS!U12+VENTAS!W12 -> 0 | G17: =VENTAS!Z12+VENTAS!AB12 -> 0 | H17: =VENTAS!AE12+VENTAS!AG12 -> 1 | I17: =VENTAS!AJ12+VENTAS!AL12 -> 0 | J17: 0 | K17: =VENTAS!AT12+VENTAS!AV12 -> 0 | L17: =VENTAS!AY12+VENTAS!BA12 -> 0 | M17: 0 | N17: 0 | O17: 0
A18: manilla tatacoa | B18: 1500 | C18: =VENTAS!E13+VENTAS!G13 -> 0 | D18: =VENTAS!K13+VENTAS!M13 -> 1 | E18: =VENTAS!P13+VENTAS!R13 -> 0 | F18: =VENTAS!U13+VENTAS!W13 -> 3 | G18: =VENTAS!Z13+VENTAS!AB13 -> 0 | H18: =VENTAS!AE13+VENTAS!AG13 -> 0 | I18: =VENTAS!AJ13+VENTAS!AL13 -> 0 | J18: 0 | K18: =VENTAS!AT13+VENTAS!AV13 -> 0 | L18: =VENTAS!AY13+VENTAS!BA13 -> 0 | M18: 0 | N18: 0 | O18: 0
A19: fotos pequeñas | B19: 600 | C19: =VENTAS!E14+VENTAS!G14 -> 0 | D19: =VENTAS!K14+VENTAS!M14 -> 8 | E19: =VENTAS!P14+VENTAS!R14 -> 0 | F19: =VENTAS!U14+VENTAS!W14 -> 5 | G19: =VENTAS!Z14+VENTAS!AB14 -> 0 | H19: =VENTAS!AE14+VENTAS!AG14 -> 2 | I19: =VENTAS!AJ14+VENTAS!AL14 -> 0 | J19: 0 | K19: =VENTAS!AT14+VENTAS!AV14 -> 4 | L19: =VENTAS!AY14+VENTAS!BA14 -> 2 | M19: 0 | N19: 0 | O19: 0
A20: fotos grandes | B20: 1000 | C20: =VENTAS!E15+VENTAS!G15 -> 0 | D20: =VENTAS!K15+VENTAS!M15 -> 8 | E20: =VENTAS!P15+VENTAS!R15 -> 0 | F20: =VENTAS!U15+VENTAS!W15 -> 2 | G20: =VENTAS!Z15+VENTAS!AB15 -> 0 | H20: =VENTAS!AE15+VENTAS!AG15 -> 1 | I20: =VENTAS!AJ15+VENTAS!AL15 -> 1 | J20: 0 | K20: =VENTAS!AT15+VENTAS!AV15 -> 1 | L20: =VENTAS!AY15+VENTAS!BA15 -> 2 | M20: 0 | N20: 0 | O20: 0
A21: bolsas de tela | B21: 15000 | C21: - | D21: - | E21: =VENTAS!P18+VENTAS!R18 -> 0 | F21: =VENTAS!U18+VENTAS!W18 -> 0 | G21: =VENTAS!Z18+VENTAS!AB18 -> 0 | H21: =VENTAS!AE18+VENTAS!AG18 -> 0 | I21: =VENTAS!AJ18+VENTAS!AL18 -> 0 | J21: 0 | K21: =VENTAS!AT18+VENTAS!AV18 -> 1 | L21: 0 | M21: 0 | N21: 0 | O21: 0
A22: esfero cohete | B22: 6000 | C22: - | D22: - | E22: =VENTAS!P19+VENTAS!R19 -> 0 | F22: =VENTAS!U19+VENTAS!W19 -> 1 | G22: =VENTAS!Z19+VENTAS!AB19 -> 0 | H22: =VENTAS!AE19+VENTAS!AG19 -> 1 | I22: =VENTAS!AJ19+VENTAS!AL19 -> 2 | J22: 0 | K22: =VENTAS!AT19+VENTAS!AV19 -> 5 | L22: 1 | M22: 2 | N22: 0 | O22: 4
A23: mousepad | B23: 9500 | C23: - | D23: - | E23: =VENTAS!P20+VENTAS!R20 -> 1 | F23: =VENTAS!U20+VENTAS!W20 -> 1 | G23: =VENTAS!Z20+VENTAS!AB20 -> 0 | H23: =VENTAS!AE20+VENTAS!AG20 -> 0 | I23: =VENTAS!AJ20+VENTAS!AL20 -> 2 | J23: 0 | K23: =VENTAS!AT20+VENTAS!AV20 -> 4 | L23: 1 | M23: 0 | N23: 0 | O23: 0
A24: tula de planetas | B24: 14000 | C24: - | D24: - | E24: =VENTAS!P21+VENTAS!R21 -> 0 | F24: =VENTAS!U21+VENTAS!W21 -> 2 | G24: =VENTAS!Z21+VENTAS!AB21 -> 0 | H24: =VENTAS!AE21+VENTAS!AG21 -> 1 | I24: =VENTAS!AJ21+VENTAS!AL21 -> 1 | J24: 0 | K24: =VENTAS!AT21+VENTAS!AV21 -> 1 | L24: 0 | M24: 0 | N24: 2 | O24: 0
A25: cuadernos exploración | B25: 10000 | C25: - | D25: - | E25: =VENTAS!P22+VENTAS!R22 -> 2 | F25: =VENTAS!U22+VENTAS!W22 -> 1 | G25: =VENTAS!Z22+VENTAS!AB22 -> 2 | H25: =VENTAS!AE22+VENTAS!AG22 -> 1 | I25: =VENTAS!AJ22+VENTAS!AL22 -> 2 | J25: 1 | K25: =VENTAS!AT22+VENTAS!AV22 -> 1 | L25: 0 | M25: 0 | N25: 2 | O25: 0
A26: gorra nasa | B26: 15000 | C26: - | D26: - | E26: =VENTAS!P23+VENTAS!R23 -> 0 | F26: =VENTAS!U23+VENTAS!W23 -> 0 | G26: =VENTAS!Z23+VENTAS!AB23 -> 0 | H26: =VENTAS!AE23+VENTAS!AG23 -> 1 | I26: =VENTAS!AJ23+VENTAS!AL23 -> 1 | J26: 0 | K26: =VENTAS!AT23+VENTAS!AV23 -> 4 | L26: =VENTAS!AY21+VENTAS!BA21 -> 0 | M26: 0 | N26: 0 | O26: 0
A27: botilito | B27: 21000 | C27: - | D27: - | E27: - | F27: =VENTAS!U25+VENTAS!W25 -> 1 | G27: =VENTAS!Z25+VENTAS!AB25 -> 2 | H27: =VENTAS!AE25+VENTAS!AG25 -> 0 | I27: =VENTAS!AJ25+VENTAS!AL25 -> 1 | J27: 0 | K27: =VENTAS!AT25+VENTAS!AV25 -> 0 | L27: =VENTAS!AY22+VENTAS!BA22 -> 0 | M27: 0 | N27: 0 | O27: 0
A28: saldo Galilea | B28: =SUM(C28:K28) -> 1307400 | C28: =SUMPRODUCT(C7:C27,$B$7:$B$27) -> 184500 | D28: =SUMPRODUCT(D7:D27,$B$7:$B$27) -> 101800 | E28: =SUMPRODUCT(E7:E26,$B$7:$B$26) -> 38500 | F28: =SUMPRODUCT(F7:F27,$B$7:$B$27) -> 112000 | G28: =SUMPRODUCT(G7:G27,$B$7:$B$27) -> 138000 | H28: =SUMPRODUCT(H7:H27,$B$7:$B$27) -> 155200 | I28: =SUMPRODUCT(I7:I27,$B$7:$B$27) -> 143500 | J28: =SUMPRODUCT(J7:J27,$B$7:$B$27) -> 38000 | K28: =SUMPRODUCT(K7:K27,$B$7:$B$27) -> 395900 | L28: =SUMPRODUCT(L7:L27,$B$7:$B$27) -> 49700 | M28: =SUMPRODUCT(M7:M27,$B$7:$B$27) -> 19000 | ... O28: =SUMPRODUCT(O7:O27,$B$7:$B$27) -> 96000
A29: aretes | B29: 12000 | C29: =VENTAS!E16+VENTAS!G16 -> 1 | D29: =VENTAS!K16+VENTAS!M16 -> 3 | E29: =VENTAS!P16+VENTAS!R16 -> 0 | F29: =VENTAS!W16+VENTAS!W16 -> 0 | G29: =VENTAS!Z16+VENTAS!AB16 -> 0 | H29: =VENTAS!AE16+VENTAS!AG16 -> 0 | I29: =VENTAS!AJ16+VENTAS!AL16 -> 0 | J29: 0 | K29: 0 | L29: 2 | M29: 0 | N29: 0
A30: carta celeste | B30: 25000 | C30: =VENTAS!E17+VENTAS!G17 -> 1 | D30: - | E30: - | F30: - | G30: - | H30: - | I30: - | J30: - | K30: - | L30: 0 | M30: - | N30: 0
A31: saldo Sebas | B31: =SUM(C31:K31) -> 73000 | C31: =SUMPRODUCT(C29:C30,$B$29:$B$30) -> 37000 | D31: =SUMPRODUCT(D29:D30,$B$29:$B$30) -> 36000 | E31: =SUMPRODUCT(E29:E30,$B$29:$B$30) -> 0 | F31: =SUMPRODUCT(F29:F30,$B$29:$B$30) -> 0 | G31: =SUMPRODUCT(G29:G30,$B$29:$B$30) -> 0 | H31: =SUMPRODUCT(H29:H30,$B$29:$B$30) -> 0 | I31: =SUMPRODUCT(I29:I30,$B$29:$B$30) -> 0 | J31: =SUMPRODUCT(J29:J30,$B$29:$B$30) -> 0 | ... O31: =SUMPRODUCT(O29:O30,$B$29:$B$30) -> 0
A32: libro Juno | B32: 22000 | C32: - | D32: - | E32: - | F32: =VENTAS!U24+VENTAS!W24 -> 1 | G32: =VENTAS!Z24+VENTAS!AB24 -> 2 | H32: =VENTAS!AE24+VENTAS!AG24 -> 1 | I32: =VENTAS!AJ24+VENTAS!AL24 -> 1 | J32: 0 | K32: 7 | L32: 0 | M32: 0 | N32: 0
A33: saldo Santiago | B33: =SUM(C33:K33) -> 264000 | C33: =C32 -> - | D33: =D32 -> - | E33: =E32 -> - | F33: =F32*$B$32 -> 22000 | G33: =G32*$B$32 -> 44000 | H33: =H32*$B$32 -> 22000 | I33: =I32*$B$32 -> 22000 | J33: =J32*$B$32 -> 0 | K33: =K32*$B$32 -> 154000 | L33: =L32*$B$32 -> 0 | M33: =M32*$B$32 -> 0 | ... O33: =O32*$B$32 -> 0

Sheet INVENTARIO
A1: PRODUCTO | C1: 45250 | D1: NUEVOS 22/11 | E1: VENDIDOS | F1: DESEADOS | G1: 45261 | H1: COMPARACIÓN | I1: 45273 | J1: VENDIDOS | K1: COMPARACIÓN | L1: TOTAL VENTAS | M1: DESEADOS | N1: diferencia | O1: desbalance
A2: pin artesanal | B2: 14000 | C2: 19 | D2: 0 | E2: 1 | F2: =C2-E2+D2 -> 18 | G2: 18 | H2: =F2-G2 -> 0 | I2: 18 | J2: 1 | K2: =I2+J2-G2 -> 1 | L2: 2 | M2: =C2-L2+D2 -> 17 | N2: =I2-M2 -> 1 | O2: =N2*B2 -> 14000 | P2: 17 | Q2: =M2-P2 -> 0 | R2: =$B2*Q2 -> 0
A3: pin metálico | B3: 7000 | C3: 38 | D3: 18 | E3: 15 | F3: =C3-E3+D3 -> 41 | G3: 36 | H3: =F3-G3 -> 5 | I3: 19 | J3: 19 | K3: =I3+J3-G3 -> 2 | L3: 30 | M3: =C3-L3+D3 -> 26 | N3: =I3-M3 -> -7 | O3: =N3*B3 -> -49000 | P3: 20 | Q3: =M3-P3 -> 6 | R3: =$B3*Q3 -> 42000 | V3: pines | W3: 6
A4: lápices luna y planetas | B4: 3000 | C4: 146 | D4: 0 | E4: 10 | F4: =C4-E4+D4 -> 136 | G4: 136 | H4: =F4-G4 -> 0 | I4: 129 | J4: 4 | K4: =I4+J4-G4 -> -3 | L4: 15 | M4: =C4-L4+D4 -> 131 | N4: =I4-M4 -> -2 | O4: =N4*B4 -> -6000 | P4: 128 | Q4: =M4-P4 -> 3 | R4: =$B4*Q4 -> 9000 | V4: lápices | W4: 3
A5: esfero astronauta | B5: 6000 | C5: 11 | D5: 15 | E5: 11 | F5: =C5-E5+D5 -> 15 | G5: 12 | H5: =F5-G5 -> 3 | I5: 7 | J5: 18 | K5: =I5+J5-G5 -> 13 | L5: 30 | M5: =C5-L5+D5+15 -> 11 | N5: =I5-M5 -> -4 | O5: =N5*B5 -> -24000 | P5: 1 | Q5: =M5-P5 -> 10 | R5: =$B5*Q5 -> 60000 | V5: esferos | W5: 18
A6: cuaderno | B6: 7000 | C6: 1 | D6: 0 | E6: 1 | F6: =C6-E6+D6 -> 0 | G6: 0 | H6: =F6-G6 -> 0 | I6: 0 | J6: 0 | K6: =I6+J6-G6 -> 0 | L6: 1 | M6: =C6-L6+D6 -> 0 | N6: =I6-M6 -> 0 | O6: =N6*B6 -> 0 | P6: 0 | Q6: =M6-P6 -> 0 | R6: =$B6*Q6 -> 0 | V6: manilla | W6: 4
A7: adhesivo luminoso | B7: 5000 | C7: 2 | D7: 11 | E7: 8 | F7: =C7-E7+D7 -> 5 | G7: 3 | H7: =F7-G7 -> 2 | I7: 0 | J7: 3 | K7: =I7+J7-G7 -> 0 | L7: 11 | M7: =C7-L7+D7 -> 2 | N7: =I7-M7 -> -2 | O7: =N7*B7 -> -10000 | P7: 0 | Q7: =M7-P7 -> 2 | R7: =$B7*Q7 -> 10000 | V7: adhesivo luminoso | W7: 2
A8: cartuchera | B8: 8000 | C8: 5 | D8: 0 | E8: 0 | F8: =C8-E8+D8 -> 5 | G8: 5 | H8: =F8-G8 -> 0 | I8: 3 | J8: 1 | K8: =I8+J8-G8 -> -1 | L8: 1 | M8: =C8-L8+D8 -> 4 | N8: =I8-M8 -> -1 | O8: =N8*B8 -> -8000 | P8: 3 | Q8: =M8-P8 -> 1 | R8: =$B8*Q8 -> 8000 | V8: cartuchera | W8: 1
A9: monedero | B9: 6000 | C9: 25 | D9: 0 | E9: 4 | F9: =C9-E9+D9 -> 21 | G9: 22 | H9: =F9-G9 -> -1 | I9: 12 | J9: 10 | K9: =I9+J9-G9 -> 0 | L9: 15 | M9: =C9-L9+D9 -> 10 | N9: =I9-M9 -> 2 | O9: =N9*B9 -> 12000 | P9: 11 | Q9: =M9-P9 -> -1 | R9: =$B9*Q9 -> -6000 | V9: bolsas de tela | W9: 1
A10: manilla eclipse sol | B10: 1500 | C10: 5 | D10: 0 | E10: 2 | F10: =C10-E10+D10 -> 3 | G10: 9 | H10: =F10-G10 -> -6 | I10: 1 | J10: 5 | K10: =I10+J10-G10 -> -3 | L10: 7 | M10: =C10-L10+D10 -> -2 | N10: =I10-M10 -> 3 | O10: =N10*B10 -> 4500 | P10: 1 | Q10: =M10-P10 -> -3 | R10: =$B10*Q10 -> -4500
A11: manilla eclipse luna | B11: 1500 | C11: 10 | D11: 0 | E11: 1 | F11: =C11-E11+D11 -> 9 | G11: 0 | H11: =F11-G11 -> 9 | I11: 5 | J11: 0 | K11: =I11+J11-G11 -> 5 | L11: 1 | M11: =C11-L11+D11 -> 9 | N11: =I11-M11 -> -4 | O11: =N11*B11 -> -6000 | P11: 5 | Q11: =M11-P11 -> 4 | R11: =$B11*Q11 -> 6000
A12: manilla tatacoa | B12: 1500 | C12: 189 | D12: 0 | E12: 3 | F12: =C12-E12+D12 -> 186 | G12: 186 | H12: =F12-G12 -> 0 | I12: 173 | J12: 0 | K12: =I12+J12-G12 -> -13 | L12: 3 | M12: =C12-L12+D12 -> 186 | N12: =I12-M12 -> -13 | O12: =N12*B12 -> -19500 | P12: 186 | Q12: =M12-P12 -> 0 | R12: =$B12*Q12 -> 0
A13: fotos pequeñas | B13: 600 | C13: 34 | D13: 0 | E13: 7 | F13: =C13-E13+D13 -> 27 | G13: 27 | H13: =F13-G13 -> 0 | I13: 21 | J13: 6 | K13: =I13+J13-G13 -> 0 | L13: 13 | M13: =C13-L13+D13 -> 21 | N13: =I13-M13 -> 0 | O13: =N13*B13 -> 0 | P13: 21 | Q13: =M13-P13 -> 0 | R13: =$B13*Q13 -> 0
A14: fotos grandes | B14: 1000 | C14: 144 | D14: 0 | E14: 4 | F14: =C14-E14+D14 -> 140 | G14: =57+51+32 -> 140 | H14: =F14-G14 -> 0 | I14: 137 | J14: 3 | K14: =I14+J14-G14 -> 0 | L14: 7 | M14: =C14-L14+D14 -> 137 | N14: =I14-M14 -> 0 | O14: =N14*B14 -> 0 | P14: 138 | Q14: =M14-P14 -> -1 | R14: =$B14*Q14 -> -1000
A15: bolsas de tela | B15: 15000 | C15: 5 | D15: 0 | E15: 0 | F15: =C15-E15+D15 -> 5 | G15: 5 | H15: =F15-G15 -> 0 | I15: 3 | J15: 1 | K15: =I15+J15-G15 -> -1 | L15: 1 | M15: =C15-L15+D15 -> 4 | N15: =I15-M15 -> -1 | O15: =N15*B15 -> -15000 | P15: 3 | Q15: =M15-P15 -> 1 | R15: =$B15*Q15 -> 15000
A16: esfero cohete | B16: 6000 | C16: 8 | D16: 15 | E16: 4 | F16: =C16-E16+D16 -> 19 | G16: 14 | H16: =F16-G16 -> 5 | I16: 21 | J16: 8 | K16: =I16+J16-G16 -> 15 | L16: 12 | M16: =C16-L16+D16+15 -> 26 | N16: =I16-M16 -> -5 | O16: =N16*B16 -> -30000 | P16: 18 | Q16: =M16-P16 -> 8 | R16: =$B16*Q16 -> 48000
A17: mousepad | B17: 9500 | C17: 9 | D17: 0 | E17: 4 | F17: =C17-E17+D17 -> 5 | G17: 6 | H17: =F17-G17 -> -1 | I17: 1 | J17: 5 | K17: =I17+J17-G17 -> 0 | L17: 9 | M17: =C17-L17+D17 -> 0 | N17: =I17-M17 -> 1 | O17: =N17*B17 -> 9500 | P17: 1 | Q17: =M17-P17 -> -1 | R17: =$B17*Q17 -> -9500
A18: tula de planetas | B18: 14000 | C18: 1 | D18: 6 | E18: 4 | F18: =C18-E18+D18 -> 3 | G18: 3 | H18: =F18-G18 -> 0 | I18: 0 | J18: 3 | K18: =I18+J18-G18 -> 0 | L18: 7 | M18: =C18-L18+D18 -> 0 | N18: =I18-M18 -> 0 | O18: =N18*B18 -> 0 | P18: 0 | Q18: =M18-P18 -> 0 | R18: =$B18*Q18 -> 0
A19: cuadernos exploración | B19: 10000 | C19: 3 | D19: 9 | E19: 9 | F19: =C19-E19+D19 -> 3 | G19: 5 | H19: =F19-G19 -> -2 | I19: 1 | J19: 4 | K19: =I19+J19-G19 -> 0 | L19: 12 | M19: =C19-L19+D19 -> 0 | N19: =I19-M19 -> 1 | O19: =N19*B19 -> 10000 | P19: 1 | Q19: =M19-P19 -> -1 | R19: =$B19*Q19 -> -10000
A20: gorra nasa | B20: 15000 | C20: 6 | D20: 0 | E20: 2 | F20: =C20-E20+D20 -> 4 | G20: 4 | H20: =F20-G20 -> 0 | I20: 0 | J20: 4 | K20: =I20+J20-G20 -> 0 | L20: 6 | M20: =C20-L20+D20 -> 0 | N20: =I20-M20 -> 0 | O20: =N20*B20 -> 0 | P20: 0 | Q20: =M20-P20 -> 0 | R20: =$B20*Q20 -> 0
A21: botilito | B21: 22000 | C21: 0 | D21: 5 | E21: 4 | F21: =C21-E21+D21 -> 1 | G21: 1 | H21: =F21-G21 -> 0 | I21: 1 | J21: 0 | K21: =I21+J21-G21 -> 0 | L21: 4 | M21: =C21-L21+D21 -> 1 | N21: =I21-M21 -> 0 | O21: =N21*B21 -> 0 | P21: 1 | Q21: =M21-P21 -> 0 | R21: =$B21*Q21 -> 0
A22: Gafas | O22: =SUM(O2:O21) -> -117500 | P22: 8 | Q22: =M22-P22 -> -8 | R22: =SUM(R2:R21) -> 167000
A23: Libros santi | P23: 10 | Q23: =M23-P23 -> -10
A24: Libros goez | P24: 10 | Q24: =M24-P24 -> -10
A25: Libros Sebas

Sheet PROVEEDORES
B1: PAGO 1 GALILEA | G1: PAGO 1 SANTIAGO
B2: PRODUCTO | C2: COSTO | D2: VENDIDOS | E2: DINERO | G2: PRODUCTO | H2: COSTO | I2: VENDIDOS | J2: DINERO
B3: pin troquelado | C3: 14000 | D3: 1 | E3: =C3*D3 -> 14000 | G3: cuento Juno | H3: 22000 | I3: 12 | J3: =I3*H3 -> 264000
B4: pin metálico | C4: 7000 | D4: 7 | E4: =C4*D4 -> 49000 | G4: ABONO 07/12 | H4: 264000 | I4: DEUDA | J4: =J3 -> 264000
B5: lápices | C5: 3000 | D5: 10 | E5: =C5*D5 -> 30000
B6: esfero astronauta | C6: 6000 | D6: 5 | E6: =C6*D6 -> 30000
B7: cuaderno | C7: 7000 | D7: 8 | E7: =C7*D7 -> 56000
B8: adhesivo luminoso | C8: 5000 | D8: 8 | E8: =C8*D8 -> 40000
B9: cartuchera | C9: 8000 | D9: 3 | E9: =C9*D9 -> 24000
B10: monedero | C10: 6000 | D10: 1 | E10: =C10*D10 -> 6000
B11: cuaderno colores | C11: 10000 | D11: 2 | E11: =C11*D11 -> 20000
B12: manillas | C12: 1500 | D12: 7 | E12: =C12*D12 -> 10500
B13: postal pequeña | C13: 600 | D13: 11 | E13: =C13*D13 -> 6600
B14: postal grande | C14: 1000 | D14: 12 | E14: =C14*D14 -> 12000
B15: ABONO 18/11 | C15: 298100 | D15: DEUDA | E15: =SUM(E2:E14) -> 298100
B17: PAGO 2 GALILEA
B18: PRODUCTO | C18: COSTO | D18: VENDIDOS | E18: DINERO
B19: pin metálico | C19: 7000 | D19: 4 | E19: =C19*D19 -> 28000
B20: manilla tatacoa | C20: 1500 | D20: 3 | E20: =C20*D20 -> 4500
B21: fotos pequeñas | C21: 600 | D21: 5 | E21: =C21*D21 -> 3000
B22: fotos grandes | C22: 1000 | D22: 2 | E22: =C22*D22 -> 2000
B23: esfero cohete | C23: 6000 | D23: 1 | E23: =C23*D23 -> 6000
B24: mousepad | C24: 9500 | D24: 2 | E24: =C24*D24 -> 19000
B25: tula de planetas | C25: 14000 | D25: 2 | E25: =C25*D25 -> 28000
B26: cuadernos exploración | C26: 10000 | D26: 3 | E26: =C26*D26 -> 30000
B27: bolitito | C27: 21000 | D27: 1 | E27: =C27*D27 -> 21000
B28: lápices | C28: 3000 | D28: 1 | E28: =C28*D28 -> 3000
B29: monedero | C29: 6000 | D29: 1 | E29: =C29*D29 -> 6000
B30: ABONO 23/11 | C30: 150500 | D30: DEUDA | E30: =SUM(E19:E29) -> 150500
B32: PAGO 3 GALILEA
B33: PRODUCTO | C33: COSTO | D33: VENDIDOS | E33: DINERO
B34: pin artesanal | C34: 14000 | D34: 1 | E34: =C34*D34 -> 14000
B35: pin metálico | C35: 7000 | D35: 7 | E35: =C35*D35 -> 49000
B36: lápices | C36: 3000 | D36: 9 | E36: =C36*D36 -> 27000
B37: esfero astronauta | C37: 6000 | D37: 11 | E37: =C37*D37 -> 66000
B38: libreta | C38: 7000 | D38: 1 | E38: =C38*D38 -> 7000
B39: adhesivo luminoso | C39: 5000 | D39: 8 | E39: =C39*D39 -> 40000
B40: monedero | C40: 6000 | D40: 3 | E40: =C40*D40 -> 18000
B41: manilla eclipse sol | C41: 1500 | D41: 2 | E41: =C41*D41 -> 3000
B42: manilla eclipse luna | C42: 1500 | D42: 1 | E42: =C42*D42 -> 1500
...

Sheet VIÁTICOS
A1: NOMBRE | B1: SALDO | C1: GASTOS | D1: AJUSTE | E1: IPARM | F1: 45246 | H1: FEM | I1: 45247 | K1: OAN | L1: 45250 | N1: OAN/FEM | O1: 45253 | Q1: OAN | R1: 45254 | T1: MACARA | U1: 45255 | W1: MACARA | X1: 45256 | Z1: OAN | AA1: 45261 | AC1: UN | AD1: 45263 | AF1: OAN | AG1: 45267 | AI1: Fómeque | AJ1: 45270 | AL1: OAN | AM1: 45272 | AO1: virtual | AP1: 14/14
A2: ganancias totales | B2: =SUM(B3:B30)-B14-B21 -> 108922.92 | C2: =SUM(C3:C30) -> 397627.08 | D2: =SUM(D3:D26) -> 167475 | E2: =BALANCE!C4*0.5 -> 50750 | F2: =SUM(F3:F50) -> 1 | G2: =SUM(G3:G30) -> 50750 | H2: =BALANCE!D4*0.5 -> 36100 | I2: =SUM(I3:I50) -> 1 | J2: =SUM(J3:J30) -> 36100 | K2: =BALANCE!E4*0.5 -> 8750 | L2: =SUM(L3:L50) -> 1 | M2: =SUM(M3:M21) -> 4375 | N2: =BALANCE!F4*0.5 -> 42100 | O2: =SUM(O3:O50) -> 1 | P2: =SUM(P3:P30) -> 42100 | Q2: =BALANCE!G4*0.5 -> 42000 | R2: =SUM(R3:R50) -> 1 | S2: =SUM(S3:S30) -> 42000 | T2: =BALANCE!H4*0.5 -> 78400 | U2: =SUM(U3:U50) -> 1 | V2: =SUM(V3:V30) -> 78400 | W2: =BALANCE!I4*0.5 -> 36250 | X2: =SUM(X3:X50) -> 1 | Y2: =SUM(Y3:Y30) -> 36250 | Z2: =BALANCE!J4*0.5 -> 7500 | AA2: =SUM(AA3:AA50) -> 1 | AB2: =SUM(AB3:AB21) -> 2812.5 | AC2: =BALANCE!K4*0.5 -> 126550 | AD2: =SUM(AD3:AD50) -> 1 | AE2: =SUM(AE3:AE30) -> 126550 | AF2: =BALANCE!L4*0.5 -> 18650 | AG2: =SUM(AG3:AG50) -> 1 | AH2: =SUM(AH3:AH30) -> 18650 | AI2: =BALANCE!M4*0.5 -> 12500 | AJ2: =SUM(AJ3:AJ50) -> 1 | AK2: =SUM(AK3:AK30) -> 12500 | AL2: =BALANCE!N4*0.5 -> 19000 | AM2: =SUM(AM3:AM50) -> 1 | AN2: =SUM(AN3:AN30) -> 19000 | AO2: =BALANCE!O4*0.5 -> 28000 | AP2: =SUM(AP3:AP50) -> 1 | AQ2: =SUM(AQ3:AQ30) -> 28000
A3: Andrés Torres | B3: =SUM(-C3+G3+J3+M3+P3+S3+V3+Y3+AB3+AE3+AH3+AK3+AN3+AQ3) -> 112.5 | C3: =SUMIF(GASTOS!$F$1:$F$49,A3,GASTOS!$D$1:$D$49) -> 63000 | D3: =COUNTIF(E3:AQ3,">6")*2300 -> 9200 | E3: 0 | F3: =E3/SUM(E$3:E$50) -> 0 | G3: =F3*$E$2 -> 0 | H3: 0 | I3: =H3/SUM(H$3:H$50) -> 0 | J3: =I3*$E$2 -> 0 | K3: 0 | L3: =K3/SUM(K$3:K$50) -> 0 | M3: =L3*$E$2 -> 0 | N3: 0 | O3: =N3/SUM(N$3:N$50) -> 0 | P3: =O3*$E$2 -> 0 | Q3: 0 | R3: =Q3/SUM(Q$3:Q$50) -> 0 | S3: =R3*Q$2 -> 0 | T3: 5 | U3: =T3/SUM(T$3:T$50) -> 0.25 | V3: =U3*T$2 -> 19600 | W3: 5 | X3: =W3/SUM(W$3:W$50) -> 0.25 | Y3: =X3*W$2 -> 9062.5 | Z3: 3 | AA3: =Z3/SUM(Z$3:Z$50) -> 0.375 | AB3: =AA3*Z$2 -> 2812.5 | AC3: 5 | AD3: =AC3/SUM(AC$3:AC$50) -> 0.25 | AE3: =AD3*AC$2 -> 31637.5 | AF3: 0 | AG3: =AF3/SUM(AF$3:AF$50) -> 0 | AH3: =AG3*AF$2 -> 0 | AI3: 0 | AJ3: =AI3/SUM(AI$3:AI$50) -> 0 | AK3: =AJ3*AI$2 -> 0 | AL3: 0 | AM3: =AL3/SUM(AL$3:AL$50) -> 0 | AN3: =AM3*AL$2 -> 0 | AO3: 0 | AP3: =AO3/SUM(AO$3:AO$50) -> 0 | AQ3: =AP3*AO$2 -> 0
A4: Cristian Gómez | B4: =SUM(-C4+G4+J4+M4+P4+S4+V4+Y4+AB4+AE4+AH4+AK4+AN4+AQ4) -> 0 | C4: =SUMIF(GASTOS!$F$1:$F$49,A4,GASTOS!$D$1:$D$49) -> 34102.75 | D4: =COUNTIF(E4:AQ4,">6")*2300 -> 6900 | E4: 0 | F4: =E4/SUM(E$3:E$50) -> 0 | G4: =F4*$E$2 -> 0 | H4: 0 | I4: =H4/SUM(H$3:H$50) -> 0 | J4: =I4*$E$2 -> 0 | K4: 0 | L4: =K4/SUM(K$3:K$50) -> 0 | M4: =L4*$E$2 -> 0 | N4: 1 | O4: =N4/SUM(N$3:N$50) -> 0.04 | P4: =O4*$N$2 -> 1684 | Q4: 0 | R4: =Q4/SUM(Q$3:Q$50) -> 0 | S4: =R4*$E$2 -> 0 | T4: 0 | U4: =T4/SUM(T$3:T$50) -> 0 | V4: =U4*$Z$2 -> 0 | W4: 0 | X4: =W4/SUM(W$3:W$50) -> 0 | Y4: =X4*$Z$2 -> 0 | Z4: 0 | AA4: =Z4/SUM(Z$3:Z$50) -> 0 | AB4: =AA4*$Z$2 -> 0 | AC4: 5 | AD4: =AC4/SUM(AC$3:AC$50) -> 0.25 | AE4: =AD4*AC$2 -> 31637.5 | AF4: 0 | AG4: =AF4/SUM(AF$3:AF$50) -> 0 | AH4: =AG4*AF$2 -> 0 | AI4: 5 | AJ4: =AI4/SUM(AI$3:AI$50) -> 0.0625 | AK4: =AJ4*AI$2 -> 781.25 | AL4: 0 | AM4: =AL4/SUM(AL$3:AL$50) -> 0 | AN4: =AM4*AL$2 -> 0 | AO4: 0 | AP4: =AO4/SUM(AO$3:AO$50) -> 0 | AQ4: =AP4*AO$2 -> 0
A5: Daniel Poveda Ruiz | B5: =SUM(-C5+G5+J5+M5+P5+S5+V5+Y5+AB5+AE5+AH5+AK5+AN5+AQ5) -> 6039.0526 | C5: =SUMIF(GASTOS!$F$1:$F$49,A5,GASTOS!$D$1:$D$49) -> 0 | D5: =COUNTIF(E5:AQ5,">6")*2300 -> 4600 | E5: 1 | F5: =E5/SUM(E$3:E$50) -> 0.052631579 | G5: =F5*$E$2 -> 2671.0526 | H5: 0 | I5: =H5/SUM(H$3:H$50) -> 0 | J5: =I5*H$2 -> 0 | K5: 0 | L5: =K5/SUM(K$3:K$50) -> 0 | M5: =L5*K$2 -> 0 | N5: 2 | O5: =N5/SUM(N$3:N$50) -> 0.08 | P5: =O5*N$2 -> 3368 | Q5: 0 | R5: =Q5/SUM(Q$3:Q$50) -> 0 | S5: =R5*Q$2 -> 0 | T5: 0 | U5: =T5/SUM(T$3:T$50) -> 0 | V5: =U5*T$2 -> 0 | W5: 0 | X5: =W5/SUM(W$3:W$50) -> 0 | Y5: =X5*W$2 -> 0 | Z5: 0 | AA5: =Z5/SUM(Z$3:Z$50) -> 0 | AB5: =AA5*Z$2 -> 0 | AC5: 0 | AD5: =AC5/SUM(AC$3:AC$50) -> 0 | AE5: =AD5*AC$2 -> 0 | AF5: 0 | AG5: =AF5/SUM(AF$3:AF$50) -> 0 | AH5: =AG5*AF$2 -> 0 | AI5: 0 | AJ5: =AI5/SUM(AI$3:AI$50) -> 0 | AK5: =AJ5*AI$2 -> 0 | AL5: 0 | AM5: =AL5/SUM(AL$3:AL$50) -> 0 | AN5: =AM5*AL$2 -> 0 | AO5: 0 | AP5: =AO5/SUM(AO$3:AO$50) -> 0 | AQ5: =AP5*AO$2 -> 0
A6: Felipe Gómez | B6: =SUM(-C6+G6+J6+M6+P6+S6+V6+Y6+AB6+AE6+AH6+AK6+AN6+AQ6) -> -0.11403509 | C6: =SUMIF(GASTOS!$F$1:$F$49,A6,GASTOS!$D$1:$D$49) -> 18678.75 | D6: =COUNTIF(E6:AQ6,">6")*2300 -> 11500 | E6: 1 | F6: =E6/SUM(E$3:E$50) -> 0.052631579 | G6: =F6*$E$2 -> 2671.0526 | H6: 0 | I6: =H6/SUM(H$3:H$50) -> 0 | J6: =I6*H$2 -> 0 | K6: 0 | L6: =K6/SUM(K$3:K$50) -> 0 | M6: =L6*K$2 -> 0 | N6: 2 | O6: =N6/SUM(N$3:N$50) -> 0.08 | P6: =O6*N$2 -> 3368 | Q6: 5 | R6: =Q6/SUM(Q$3:Q$50) -> 0.20833333 | S6: =R6*Q$2 -> 8750 | T6: 0 | U6: =T6/SUM(T$3:T$50) -> 0 | V6: =U6*T$2 -> 0 | W6: 0 | X6: =W6/SUM(W$3:W$50) -> 0 | Y6: =X6*W$2 -> 0 | Z6: 0 | AA6: =Z6/SUM(Z$3:Z$50) -> 0 | AB6: =AA6*Z$2 -> 0 | AC6: 0 | AD6: =AC6/SUM(AC$3:AC$50) -> 0 | AE6: =AD6*AC$2 -> 0 | AF6: 5 | AG6: =AF6/SUM(AF$3:AF$50) -> 0.16666667 | AH6: =AG6*AF$2 -> 3108.3333 | AI6: 5 | AJ6: =AI6/SUM(AI$3:AI$50) -> 0.0625 | AK6: =AJ6*AI$2 -> 781.25 | AL6: 0 | AM6: =AL6/SUM(AL$3:AL$50) -> 0 | AN6: =AM6*AL$2 -> 0 | AO6: 0 | AP6: =AO6/SUM(AO$3:AO$50) -> 0 | AQ6: =AP6*AO$2 -> 0
A7: Joseph Alejandro Niño | B7: =SUM(-C7+G7+J7+M7+P7+S7+V7+Y7+AB7+AE7+AH7+AK7+AN7+AQ7) -> 9711.5219 | C7: =SUMIF(GASTOS!$F$1:$F$49,A7,GASTOS!$D$1:$D$49) -> 6666 | D7: =COUNTIF(E7:AQ7,">6")*2300 -> 9200 | E7: 2 | F7: =E7/SUM(E$3:E$50) -> 0.10526316 | G7: =F7*$E$2 -> 5342.1053 | H7: 1 | I7: =H7/SUM(H$3:H$50) -> 0.041666667 | J7: =I7*H$2 -> 1504.1667 | K7: 0 | L7: =K7/SUM(K$3:K$50) -> 0 | M7: =L7*K$2 -> 0 | N7: 0 | O7: =N7/SUM(N$3:N$50) -> 0 | P7: =O7*N$2 -> 0 | Q7: 5 | R7: =Q7/SUM(Q$3:Q$50) -> 0.20833333 | S7: =R7*Q$2 -> 8750 | T7: 0 | U7: =T7/SUM(T$3:T$50) -> 0 | V7: =U7*T$2 -> 0 | W7: 0 | X7: =W7/SUM(W$3:W$50) -> 0 | Y7: =X7*W$2 -> 0 | Z7: 0 | AA7: =Z7/SUM(Z$3:Z$50) -> 0 | AB7: =AA7*Z$2 -> 0 | AC7: 0 | AD7: =AC7/SUM(AC$3:AC$50) -> 0 | AE7: =AD7*AC$2 -> 0 | AF7: 0 | AG7: =AF7/SUM(AF$3:AF$50) -> 0 | AH7: =AG7*AF$2 -> 0 | AI7: 5 | AJ7: =AI7/SUM(AI$3:AI$50) -> 0.0625 | AK7: =AJ7*AI$2 -> 781.25 | AL7: 0 | AM7: =AL7/SUM(AL$3:AL$50) -> 0 | AN7: =AM7*AL$2 -> 0 | AO7: 0 | AP7: =AO7/SUM(AO$3:AO$50) -> 0 | AQ7: =AP7*AO$2 -> 0
A8: Joyse Alfonso Vargas | B8: =SUM(-C8+G8+J8+M8+P8+S8+V8+Y8+AB8+AE8+AH8+AK8+AN8+AQ8) -> 4175.2193 | C8: =SUMIF(GASTOS!$F$1:$F$49,A8,GASTOS!$D$1:$D$49) -> 0 | D8: 4175 | E8: 1 | F8: =E8/SUM(E$3:E$50) -> 0.052631579 | G8: =F8*$E$2 -> 2671.0526 | H8: 1 | I8: =H8/SUM(H$3:H$50) -> 0.041666667 | J8: =I8*H$2 -> 1504.1667 | K8: 0 | L8: =K8/SUM(K$3:K$50) -> 0 | M8: =L8*K$2 -> 0 | N8: 0 | O8: =N8/SUM(N$3:N$50) -> 0 | P8: =O8*N$2 -> 0 | Q8: 0 | R8: =Q8/SUM(Q$3:Q$50) -> 0 | S8: =R8*Q$2 -> 0 | T8: 0 | U8: =T8/SUM(T$3:T$50) -> 0 | V8: =U8*T$2 -> 0 | W8: 0 | X8: =W8/SUM(W$3:W$50) -> 0 | Y8: =X8*W$2 -> 0 | Z8: 0 | AA8: =Z8/SUM(Z$3:Z$50) -> 0 | AB8: =AA8*Z$2 -> 0 | AC8: 0 | AD8: =AC8/SUM(AC$3:AC$50) -> 0 | AE8: =AD8*AC$2 -> 0 | AF8: 0 | AG8: =AF8/SUM(AF$3:AF$50) -> 0 | AH8: =AG8*AF$2 -> 0 | AI8: 0 | AJ8: =AI8/SUM(AI$3:AI$50) -> 0 | AK8: =AJ8*AI$2 -> 0 | AL8: 0 | AM8: =AL8/SUM(AL$3:AL$50) -> 0 | AN8: =AM8*AL$2 -> 0 | AO8: 0 | AP8: =AO8/SUM(AO$3:AO$50) -> 0 | AQ8: =AP8*AO$2 -> 0
A9: Juan Angel Duque | B9: =SUM(-C9+G9+J9+M9+P9+S9+V9+Y9+AB9+AE9+AH9+AK9+AN9+AQ9) -> 4223.5833 | C9: =SUMIF(GASTOS!$F$1:$F$49,A9,GASTOS!$D$1:$D$49) -> 6666 | D9: =COUNTIF(E9:AQ9,">6")*2300 -> 6900 | E9: 0 | F9: =E9/SUM(E$3:E$50) -> 0 | G9: =F9*$E$2 -> 0 | H9: 0 | I9: =H9/SUM(H$3:H$50) -> 0 | J9: =I9*$E$2 -> 0 | K9: 0 | L9: =K9/SUM(K$3:K$50) -> 0 | M9: =L9*$E$2 -> 0 | N9: 0 | O9: =N9/SUM(N$3:N$50) -> 0 | P9: =O9*$E$2 -> 0 | Q9: 4 | R9: =Q9/SUM(Q$3:Q$50) -> 0.16666667 | S9: =R9*Q$2 -> 7000 | T9: 0 | U9: =T9/SUM(T$3:T$50) -> 0 | V9: =U9*T$2 -> 0 | W9: 0 | X9: =W9/SUM(W$3:W$50) -> 0 | Y9: =X9*W$2 -> 0 | Z9: 0 | AA9: =Z9/SUM(Z$3:Z$50) -> 0 | AB9: =AA9*Z$2 -> 0 | AC9: 0 | AD9: =AC9/SUM(AC$3:AC$50) -> 0 | AE9: =AD9*AC$2 -> 0 | AF9: 5 | AG9: =AF9/SUM(AF$3:AF$50) -> 0.16666667 | AH9: =AG9*AF$2 -> 3108.3333 | AI9: 5 | AJ9: =AI9/SUM(AI$3:AI$50) -> 0.0625 | AK9: =AJ9*AI$2 -> 781.25 | AL9: 0 | AM9: =AL9/SUM(AL$3:AL$50) -> 0 | AN9: =AM9*AL$2 -> 0 | AO9: 0 | AP9: =AO9/SUM(AO$3:AO$50) -> 0 | AQ9: =AP9*AO$2 -> 0
A10: Juan Pablo Garavito | B10: =SUM(-C10+G10+J10+M10+P10+S10+V10+Y10+AB10+AE10+AH10+AK10+AN10+AQ10) -> 13999.583 | C10: =SUMIF(GASTOS!$F$1:$F$49,A10,GASTOS!$D$1:$D$49) -> 46676 | D10: =COUNTIF(E10:AQ10,">6")*2300 -> 11500 | E10: 0 | F10: =E10/SUM(E$3:E$50) -> 0 | G10: =F10*$E$2 -> 0 | H10: 5 | I10: =H10/SUM(H$3:H$50) -> 0.20833333 | J10: =I10*H$2 -> 7520.8333 | K10: 0 | L10: =K10/SUM(K$3:K$50) -> 0 | M10: =L10*K$2 -> 0 | N10: 4 | O10: =N10/SUM(N$3:N$50) -> 0.16 | P10: =O10*N$2 -> 6736 | Q10: 0 | R10: =Q10/SUM(Q$3:Q$50) -> 0 | S10: =R10*Q$2 -> 0 | T10: 0 | U10: =T10/SUM(T$3:T$50) -> 0 | V10: =U10*T$2 -> 0 | W10: 0 | X10: =W10/SUM(W$3:W$50) -> 0 | Y10: =X10*W$2 -> 0 | Z10: 0 | AA10: =Z10/SUM(Z$3:Z$50) -> 0 | AB10: =AA10*Z$2 -> 0 | AC10: 5 | AD10: =AC10/SUM(AC$3:AC$50) -> 0.25 | AE10: =AD10*AC$2 -> 31637.5 | AF10: 0 | AG10: =AF10/SUM(AF$3:AF$50) -> 0 | AH10: =AG10*AF$2 -> 0 | AI10: 5 | AJ10: =AI10/SUM(AI$3:AI$50) -> 0.0625 | AK10: =AJ10*AI$2 -> 781.25 | AL10: 0 | AM10: =AL10/SUM(AL$3:AL$50) -> 0 | AN10: =AM10*AL$2 -> 0 | AO10: 5 | AP10: =AO10/SUM(AO$3:AO$50) -> 0.5 | AQ10: =AP10*AO$2 -> 14000
A11: Julián David Acosta | B11: =SUM(-C11+G11+J11+M11+P11+S11+V11+Y11+AB11+AE11+AH11+AK11+AN11+AQ11) -> 5999.8026 | C11: =SUMIF(GASTOS!$F$1:$F$49,A11,GASTOS!$D$1:$D$49) -> 14183 | D11: =COUNTIF(E11:AQ11,">6")*2300 -> 13800 | E11: 1 | F11: =E11/SUM(E$3:E$50) -> 0.052631579 | G11: =F11*$E$2 -> 2671.0526 | H11: 1 | I11: =H11/SUM(H$3:H$50) -> 0.041666667 | J11: =I11*H$2 -> 1504.1667 | K11: 0 | L11: =K11/SUM(K$3:K$50) -> 0 | M11: =L11*K$2 -> 0 | N11: 2 | O11: =N11/SUM(N$3:N$50) -> 0.08 | P11: =O11*N$2 -> 3368 | Q11: 5 | R11: =Q11/SUM(Q$3:Q$50) -> 0.20833333 | S11: =R11*Q$2 -> 8750 | T11: 0 | U11: =T11/SUM(T$3:T$50) -> 0 | V11: =U11*T$2 -> 0 | W11: 0 | X11: =W11/SUM(W$3:W$50) -> 0 | Y11: =X11*W$2 -> 0 | Z11: 0 | AA11: =Z11/SUM(Z$3:Z$50) -> 0 | AB11: =AA11*Z$2 -> 0 | AC11: 0 | AD11: =AC11/SUM(AC$3:AC$50) -> 0 | AE11: =AD11*AC$2 -> 0 | AF11: 5 | AG11: =AF11/SUM(AF$3:AF$50) -> 0.16666667 | AH11: =AG11*AF$2 -> 3108.3333 | AI11: 5 | AJ11: =AI11/SUM(AI$3:AI$50) -> 0.0625 | AK11: =AJ11*AI$2 -> 781.25 | AL11: 0 | AM11: =AL11/SUM(AL$3:AL$50) -> 0 | AN11: =AM11*AL$2 -> 0 | AO11: 0 | AP11: =AO11/SUM(AO$3:AO$50) -> 0 | AQ11: =AP11*AO$2 -> 0
A12: Juliana Zúñiga | B12: =SUM(-C12+G12+J12+M12+P12+S12+V12+Y12+AB12+AE12+AH12+AK12+AN12+AQ12) -> 8523.5833 | C12: =SUMIF(GASTOS!$F$1:$F$49,A12,GASTOS!$D$1:$D$49) -> 55666 | D12: =COUNTIF(E12:AQ12,">6")*2300 -> 11500 | E12: 0 | F12: =E12/SUM(E$3:E$50) -> 0 | G12: =F12*$E$2 -> 0 | H12: 0 | I12: =H12/SUM(H$3:H$50) -> 0 | J12: =I12*$E$2 -> 0 | K12: 0 | L12: =K12/SUM(K$3:K$50) -> 0 | M12: =L12*$E$2 -> 0 | N12: 0 | O12: =N12/SUM(N$3:N$50) -> 0 | P12: =O12*$E$2 -> 0 | Q12: 0 | R12: =Q12/SUM(Q$3:Q$50) -> 0 | S12: =R12*Q$2 -> 0 | T12: 5 | U12: =T12/SUM(T$3:T$50) -> 0.25 | V12: =U12*T$2 -> 19600 | W12: 5 | X12: =W12/SUM(W$3:W$50) -> 0.25 | Y12: =X12*W$2 -> 9062.5 | Z12: 0 | AA12: =Z12/SUM(Z$3:Z$50) -> 0 | AB12: =AA12*Z$2 -> 0 | AC12: 5 | AD12: =AC12/SUM(AC$3:AC$50) -> 0.25 | AE12: =AD12*AC$2 -> 31637.5 | AF12: 5 | AG12: =AF12/SUM(AF$3:AF$50) -> 0.16666667 | AH12: =AG12*AF$2 -> 3108.3333 | AI12: 5 | AJ12: =AI12/SUM(AI$3:AI$50) -> 0.0625 | AK12: =AJ12*AI$2 -> 781.25 | AL12: 0 | AM12: =AL12/SUM(AL$3:AL$50) -> 0 | AN12: =AM12*AL$2 -> 0 | AO12: 0 | AP12: =AO12/SUM(AO$3:AO$50) -> 0 | AQ12: =AP12*AO$2 -> 0
A13: Laura Jiménez | B13: =SUM(-C13+G13+J13+M13+P13+S13+V13+Y13+AB13+AE13+AH13+AK13+AN13+AQ13) -> 480.26316 | C13: =SUMIF(GASTOS!$F$1:$F$49,A13,GASTOS!$D$1:$D$49) -> 26000 | D13: =COUNTIF(E13:AQ13,">6")*2300 -> 6900 | E13: 5 | F13: =E13/SUM(E$3:E$50) -> 0.26315789 | G13: =F13*$E$2 -> 13355.263 | H13: 0 | I13: =H13/SUM(H$3:H$50) -> 0 | J13: =I13*H$2 -> 0 | K13: 5 | L13: =K13/SUM(K$3:K$50) -> 0.5 | M13: =L13*K$2 -> 4375 | N13: 0 | O13: =N13/SUM(N$3:N$50) -> 0 | P13: =O13*N$2 -> 0 | Q13: 5 | R13: =Q13/SUM(Q$3:Q$50) -> 0.20833333 | S13: =R13*Q$2 -> 8750 | T13: 0 | U13: =T13/SUM(T$3:T$50) -> 0 | V13: =U13*T$2 -> 0 | W13: 0 | X13: =W13/SUM(W$3:W$50) -> 0 | Y13: =X13*W$2 -> 0 | Z13: 0 | AA13: =Z13/SUM(Z$3:Z$50) -> 0 | AB13: =AA13*Z$2 -> 0 | AC13: 0 | AD13: =AC13/SUM(AC$3:AC$50) -> 0 | AE13: =AD13*AC$2 -> 0 | AF13: 0 | AG13: =AF13/SUM(AF$3:AF$50) -> 0 | AH13: =AG13*AF$2 -> 0 | AI13: 0 | AJ13: =AI13/SUM(AI$3:AI$50) -> 0 | AK13: =AJ13*AI$2 -> 0 | AL13: 0 | AM13: =AL13/SUM(AL$3:AL$50) -> 0 | AN13: =AM13*AL$2 -> 0 | AO13: 0 | AP13: =AO13/SUM(AO$3:AO$50) -> 0 | AQ13: =AP13*AO$2 -> 0
A14: Luis Carlos "topo" | B14: =SUM(-C14+G14+J14+M14+P14+S14+V14+Y14+AB14+AE14+AH14+AK14+AN14+AQ14) -> 0 | C14: =SUMIF(GASTOS!$F$1:$F$49,A14,GASTOS!$D$1:$D$49) -> 781.25 | D14: 0 | E14: 0 | F14: =E14/SUM(E$3:E$50) -> 0 | G14: =F14*E$2 -> 0 | H14: 0 | I14: =H14/SUM(H$3:H$50) -> 0 | J14: =I14*H$2 -> 0 | K14: 0 | L14: =K14/SUM(K$3:K$50) -> 0 | M14: =L14*K$2 -> 0 | N14: 0 | O14: =N14/SUM(N$3:N$50) -> 0 | P14: =O14*N$2 -> 0 | Q14: 0 | R14: =Q14/SUM(Q$3:Q$50) -> 0 | S14: =R14*Q$2 -> 0 | T14: 0 | U14: =T14/SUM(T$3:T$50) -> 0 | V14: =U14*T$2 -> 0 | W14: 0 | X14: =W14/SUM(W$3:W$50) -> 0 | Y14: =X14*W$2 -> 0 | Z14: 0 | AA14: =Z14/SUM(Z$3:Z$50) -> 0 | AB14: =AA14*Z$2 -> 0 | AC14: 0 | AD14: =AC14/SUM(AC$3:AC$50) -> 0 | AE14: =AD14*AC$2 -> 0 | AF14: 0 | AG14: =AF14/SUM(AF$3:AF$50) -> 0 | AH14: =AG14*AF$2 -> 0 | AI14: 5 | AJ14: =AI14/SUM(AI$3:AI$50) -> 0.0625 | AK14: =AJ14*AI$2 -> 781.25 | AL14: 0 | AM14: =AL14/SUM(AL$3:AL$50) -> 0 | AN14: =AM14*AL$2 -> 0 | AO14: 0 | AP14: =AO14/SUM(AO$3:AO$50) -> 0 | AQ14: =AP14*AO$2 -> 0
A15: Luis Miguel Barbosa | B15: =SUM(-C15+G15+J15+M15+P15+S15+V15+Y15+AB15+AE15+AH15+AK15+AN15+AQ15) -> 9744.3333 | C15: =SUMIF(GASTOS!$F$1:$F$49,A15,GASTOS!$D$1:$D$49) -> 0 | D15: =COUNTIF(E15:AQ15,">6")*2300 -> 4600 | E15: 0 | F15: =E15/SUM(E$3:E$50) -> 0 | G15: =F15*$E$2 -> 0 | H15: 2 | I15: =H15/SUM(H$3:H$50) -> 0.083333333 | J15: =I15*H$2 -> 3008.3333 | K15: 0 | L15: =K15/SUM(K$3:K$50) -> 0 | M15: =L15*K$2 -> 0 | N15: 4 | O15: =N15/SUM(N$3:N$50) -> 0.16 | P15: =O15*N$2 -> 6736 | Q15: 0 | R15: =Q15/SUM(Q$3:Q$50) -> 0 | S15: =R15*Q$2 -> 0 | T15: 0 | U15: =T15/SUM(T$3:T$50) -> 0 | V15: =U15*T$2 -> 0 | W15: 0 | X15: =W15/SUM(W$3:W$50) -> 0 | Y15: =X15*W$2 -> 0 | Z15: 0 | AA15: =Z15/SUM(Z$3:Z$50) -> 0 | AB15: =AA15*Z$2 -> 0 | AC15: 0 | AD15: =AC15/SUM(AC$3:AC$50) -> 0 | AE15: =AD15*AC$2 -> 0 | AF15: 0 | AG15: =AF15/SUM(AF$3:AF$50) -> 0 | AH15: =AG15*AF$2 -> 0 | AI15: 0 | AJ15: =AI15/SUM(AI$3:AI$50) -> 0 | AK15: =AJ15*AI$2 -> 0 | AL15: 0 | AM15: =AL15/SUM(AL$3:AL$50) -> 0 | AN15: =AM15*AL$2 -> 0 | AO15: 0 | AP15: =AO15/SUM(AO$3:AO$50) -> 0 | AQ15: =AP15*AO$2 -> 0
A16: Manuel Herrera | B16: =SUM(-C16+G16+J16+M16+P16+S16+V16+Y16+AB16+AE16+AH16+AK16+AN16+AQ16) -> 5342.1053 | C16: =SUMIF(GASTOS!$F$1:$F$49,A16,GASTOS!$D$1:$D$49) -> 0 | D16: =COUNTIF(E16:AQ16,">6")*2300 -> 2300 | E16: 2 | F16: =E16/SUM(E$3:E$50) -> 0.10526316 | G16: =F16*$E$2 -> 5342.1053 | H16: 0 | I16: =H16/SUM(H$3:H$50) -> 0 | J16: =I16*H$2 -> 0 | K16: 0 | L16: =K16/SUM(K$3:K$50) -> 0 | M16: =L16*K$2 -> 0 | N16: 0 | O16: =N16/SUM(N$3:N$50) -> 0 | P16: =O16*N$2 -> 0 | Q16: 0 | R16: =Q16/SUM(Q$3:Q$50) -> 0 | S16: =R16*Q$2 -> 0 | T16: 0 | U16: =T16/SUM(T$3:T$50) -> 0 | V16: =U16*T$2 -> 0 | W16: 0 | X16: =W16/SUM(W$3:W$50) -> 0 | Y16: =X16*W$2 -> 0 | Z16: 0 | AA16: =Z16/SUM(Z$3:Z$50) -> 0 | AB16: =AA16*Z$2 -> 0 | AC16: 0 | AD16: =AC16/SUM(AC$3:AC$50) -> 0 | AE16: =AD16*AC$2 -> 0 | AF16: 0 | AG16: =AF16/SUM(AF$3:AF$50) -> 0 | AH16: =AG16*AF$2 -> 0 | AI16: 0 | AJ16: =AI16/SUM(AI$3:AI$50) -> 0 | AK16: =AJ16*AI$2 -> 0 | AL16: 0 | AM16: =AL16/SUM(AL$3:AL$50) -> 0 | AN16: =AM16*AL$2 -> 0 | AO16: 0 | AP16: =AO16/SUM(AO$3:AO$50) -> 0 | AQ16: =AP16*AO$2 -> 0
